Workbook

Sheet 受給者証情報CSV-直近1年分
A1: 利用者名 | B1: 利用者名（伏字） | C1: 利用者カナ | D1: 利用者カナ（伏字） | E1: 認定区分 | F1: 市町村番号 | G1: 市町村名 | H1: 受給者証番号 | I1: 交付年月日 | J1: 給付決定開始年月日 | K1: 給付決定終了年月日 | L1: 障害児名 | M1: 障害児名（伏字） | N1: 障害児カナ | O1: 障害児カナ（伏字） | P1: 障害児性別 | Q1: 障害児生年月日 | R1: サービス開始年月日 | S1: 多子軽減対象区分 | T1: 個別サポート加算（Ⅰ） | U1: 個別サポート加算（Ⅱ） | V1: 個別サポート加算（Ⅲ） | W1: 利用者負担割合（原則） | X1: 負担上限月額 | Y1: 上限管理事業所 | Z1: 決定サービス内容 | AA1: 決定支給量 | AB1: 支給決定開始日 | AC1: 支給決定終了日 | AD1: 契約支給事業所名 | AE1: 契約サービス内容 | AF1: 契約支給量 | AG1: 契約日 | AH1: 当該契約支給量によるサービス提供終了日 | AI1: 指定相談支援事業所名
A2: 西川 尚子 | B2: =SUBSTITUTE(REPLACE(A2,1,1,"〇"),MID(A2,LEN(A2)-1,1),"〇") -> 〇川 〇子 | C2: ニシカワ ナオコ | D2: =SUBSTITUTE(REPLACE(C2,1,1,"〇"),MID(C2,LEN(C2)-1,1),"〇") -> 〇シカワ ナ〇コ | E2: 認定済 | F2: 272070 | G2: 高槻市 | H2: 8551023818 | J2: 45108 | K2: 45473 | L2: 西川 央祐 | M2: =SUBSTITUTE(REPLACE(L2,1,1,"〇"),MID(L2,LEN(L2)-1,1),"〇") -> 〇川 〇祐 | N2: ニシカワ オウスケ | O2: =SUBSTITUTE(REPLACE(N2,1,1,"〇"),MID(N2,LEN(N2)-1,1),"〇") -> 〇シカワ オウ〇ケ | P2: 男 | Q2: 42131 | R2: 45084 | S2: 対象外 | T2: 対象外 | U2: 対象外 | W2: 1 | X2: 4600 | Z2: 放課後等デイサービス（重症心身障害児以外） | AA2: 10 | AB2: 45108 | AD2: 放課後等デイサービス きららステム西冠 | AE2: 放課後等デイサービス（重症心身障害児以外） | AF2: 5 | AG2: 45108 | AH2: 45412
A3: 山本 真佐史 | B3: =SUBSTITUTE(REPLACE(A3,1,1,"〇"),MID(A3,LEN(A3)-1,1),"〇") -> 〇本 真〇史 | C3: ヤマモト マサシ | D3: =SUBSTITUTE(REPLACE(C3,1,1,"〇"),MID(C3,LEN(C3)-1,1),"〇") -> 〇マモト マ〇シ | E3: 認定済 | F3: 272070 | G3: 高槻市 | H3: 8551011623 | I3: 45098 | J3: 45108 | K3: 45473 | L3: 山本 頼 | M3: =SUBSTITUTE(REPLACE(L3,1,1,"〇"),MID(L3,LEN(L3)-1,1),"〇") -> 〇本〇頼 | N3: ヤマモト ライ | O3: =SUBSTITUTE(REPLACE(N3,1,1,"〇"),MID(N3,LEN(N3)-1,1),"〇") -> 〇マモト 〇イ | P3: 男 | Q3: 40687 | R3: 44327 | S3: 対象外 | T3: 対象外 | U3: 対象外 | W3: 1 | X3: 4600 | Y3: 放課後等デイサービス きららドリーム沢良木 | Z3: 放課後等デイサービス（重症心身障害児以外） | AA3: 15 | AB3: 45108 | AC3: 45473 | AD3: 放課後等デイサービス きららステム西冠 | AE3: 放課後等デイサービス（重症心身障害児以外） | AF3: 5 | AG3: 45108 | AH3: 45382 | AI3: 相談支援 チェリー・ハート
A4: 古川 由香 | B4: =SUBSTITUTE(REPLACE(A4,1,1,"〇"),MID(A4,LEN(A4)-1,1),"〇") -> 〇川 〇香 | C4: フルカワ ユカ | D4: =SUBSTITUTE(REPLACE(C4,1,1,"〇"),MID(C4,LEN(C4)-1,1),"〇") -> 〇ルカワ 〇カ | E4: 認定済 | F4: 272070 | G4: 高槻市 | H4: 3100013915 | I4: 45303 | J4: 45323 | K4: 45688 | L4: 古川 丈師 | M4: =SUBSTITUTE(REPLACE(L4,1,1,"〇"),MID(L4,LEN(L4)-1,1),"〇") -> 〇川 〇師 | N4: フルカワ タケモト | O4: =SUBSTITUTE(REPLACE(N4,1,1,"〇"),MID(N4,LEN(N4)-1,1),"〇") -> 〇ルカワ タケ〇ト | P4: 男 | Q4: 39805 | R4: 44309 | S4: 対象外 | T4: 対象外 | U4: 対象外 | W4: 1 | X4: 37200 | Z4: 放課後等デイサービス（重症心身障害児以外） | AA4: 10 | AB4: 45323 | AC4: 45688 | AD4: 放課後等デイサービス きららステム西冠 | AE4: 放課後等デイサービス（重症心身障害児以外） | AF4: 5 | AG4: 45323 | AH4: 45688
A5: 寺田 葉月 | B5: =SUBSTITUTE(REPLACE(A5,1,1,"〇"),MID(A5,LEN(A5)-1,1),"〇") -> 〇田 〇月 | C5: テラダ ハヅキ | D5: =SUBSTITUTE(REPLACE(C5,1,1,"〇"),MID(C5,LEN(C5)-1,1),"〇") -> 〇ラダ ハ〇キ | E5: 認定済 | F5: 272070 | G5: 高槻市 | H5: 8551022034 | I5: 44963 | J5: 45383 | K5: 45747 | L5: 寺田 蒼空 | M5: =SUBSTITUTE(REPLACE(L5,1,1,"〇"),MID(L5,LEN(L5)-1,1),"〇") -> 〇田 〇空 | N5: テラダ ソラ | O5: =SUBSTITUTE(REPLACE(N5,1,1,"〇"),MID(N5,LEN(N5)-1,1),"〇") -> 〇ラダ 〇ラ | P5: 男 | Q5: 40958 | R5: 44794 | S5: 対象外 | T5: 対象外 | U5: 対象外 | V5: 対象外 | W5: 1 | X5: 4600 | Z5: 放課後等デイサービス（重症心身障害児以外） | AA5: 14 | AB5: 45383 | AD5: 放課後等デイサービス きららステム西冠 | AE5: 放課後等デイサービス（重症心身障害児以外） | AF5: 10 | AG5: 45383 | AH5: 45412
A6: 中杉 久代 | B6: =SUBSTITUTE(REPLACE(A6,1,1,"〇"),MID(A6,LEN(A6)-1,1),"〇") -> 〇杉 〇代 | C6: ナカスギ ヒサヨ | D6: =SUBSTITUTE(REPLACE(C6,1,1,"〇"),MID(C6,LEN(C6)-1,1),"〇") -> 〇カスギ ヒ〇ヨ | E6: 認定済 | F6: 272070 | G6: 高槻市 | H6: 8551007811 | I6: 45383 | J6: 45383 | K6: 45747 | L6: 中杉 綸之介 | M6: =SUBSTITUTE(REPLACE(L6,1,1,"〇"),MID(L6,LEN(L6)-1,1),"〇") -> 〇杉 綸〇介 | N6: ナカスギ リンノスケ | O6: =SUBSTITUTE(REPLACE(N6,1,1,"〇"),MID(N6,LEN(N6)-1,1),"〇") -> 〇カ〇ギ リンノ〇ケ | P6: 男 | Q6: 40582 | R6: 45383 | S6: 対象外 | T6: 対象外 | U6: 対象外 | V6: 対象外 | W6: 1 | X6: 4600 | Z6: 放課後等デイサービス（重症心身障害児以外） | AA6: 5 | AB6: 45383 | AC6: 45747 | AD6: 放課後等デイサービス きららステム西冠 | AE6: 放課後等デイサービス（重症心身障害児以外） | AF6: 5 | AG6: 45383 | AH6: 45747
A7: 加藤 亜希子 | B7: =SUBSTITUTE(REPLACE(A7,1,1,"〇"),MID(A7,LEN(A7)-1,1),"〇") -> 〇藤 亜〇子 | C7: カトウ アキコ | D7: =SUBSTITUTE(REPLACE(C7,1,1,"〇"),MID(C7,LEN(C7)-1,1),"〇") -> 〇トウ ア〇コ | E7: 認定済 | F7: 272070 | G7: 高槻市 | H7: 8551051892 | J7: 45474 | K7: 45838 | L7: 加藤 直人 | M7: =SUBSTITUTE(REPLACE(L7,1,1,"〇"),MID(L7,LEN(L7)-1,1),"〇") -> 〇藤 〇人 | N7: カトウ ナオト | O7: =SUBSTITUTE(REPLACE(N7,1,1,"〇"),MID(N7,LEN(N7)-1,1),"〇") -> 〇トウ ナ〇ト | P7: 男 | Q7: 42139 | R7: 45748 | S7: 対象外 | T7: 対象外 | U7: 対象外 | V7: 対象外 | W7: 1 | X7: 4600 | Y7: 放課後等デイサービス きららステム西冠 | Z7: 放課後等デイサービス（重症心身障害児以外） | AA7: 10 | AB7: 45474 | AD7: 放課後等デイサービス きららステム西冠 | AE7: 放課後等デイサービス（重症心身障害児以外） | AF7: 5 | AG7: 45474
A8: 黒田 章乃 | B8: =SUBSTITUTE(REPLACE(A8,1,1,"〇"),MID(A8,LEN(A8)-1,1),"〇") -> 〇田 〇乃 | C8: クロダ アキノ | D8: =SUBSTITUTE(REPLACE(C8,1,1,"〇"),MID(C8,LEN(C8)-1,1),"〇") -> 〇ロダ ア〇ノ | E8: 認定済 | F8: 272070 | G8: 高槻市 | H8: 8551029310 | J8: 45474 | K8: 45838 | L8: 黒田 結世 | M8: =SUBSTITUTE(REPLACE(L8,1,1,"〇"),MID(L8,LEN(L8)-1,1),"〇") -> 〇田 〇世 | N8: クロダ ユウセイ | O8: =SUBSTITUTE(REPLACE(N8,1,1,"〇"),MID(N8,LEN(N8)-1,1),"〇") -> 〇ロダ ユウ〇イ | P8: 男 | Q8: 42140 | R8: 45748 | S8: 対象外 | T8: 対象外 | U8: 対象外 | V8: 対象外 | W8: 1 | X8: 37200 | Z8: 放課後等デイサービス（重症心身障害児以外） | AA8: 10 | AB8: 45474 | AD8: 放課後等デイサービス きららステム西冠 | AE8: 放課後等デイサービス（重症心身障害児以外） | AF8: 5 | AG8: 45474
A9: 阪本 和子 | B9: =SUBSTITUTE(REPLACE(A9,1,1,"〇"),MID(A9,LEN(A9)-1,1),"〇") -> 〇本 〇子 | C9: サカモト カズコ | D9: =SUBSTITUTE(REPLACE(C9,1,1,"〇"),MID(C9,LEN(C9)-1,1),"〇") -> 〇カモト カ〇コ | E9: 認定済 | F9: 272070 | G9: 高槻市 | H9: 8551027694 | J9: 45474 | K9: 45838 | L9: 阪本 悠真 | M9: =SUBSTITUTE(REPLACE(L9,1,1,"〇"),MID(L9,LEN(L9)-1,1),"〇") -> 〇本 〇真 | N9: サカモト ユウマ | O9: =SUBSTITUTE(REPLACE(N9,1,1,"〇"),MID(N9,LEN(N9)-1,1),"〇") -> 〇カモト ユ〇マ | P9: 男 | Q9: 42499 | R9: 45748 | S9: 対象外 | T9: 対象 | U9: 対象外 | V9: 対象外 | W9: 1 | X9: 4600 | Z9: 放課後等デイサービス（重症心身障害児以外） | AA9: 10 | AB9: 45474 | AC9: 45838 | AD9: 放課後等デイサービス きららステム西冠 | AE9: 放課後等デイサービス（重症心身障害児以外） | AF9: 5 | AG9: 45748 | AH9: 45838
A10: 本郷 麻佑 | B10: =SUBSTITUTE(REPLACE(A10,1,1,"〇"),MID(A10,LEN(A10)-1,1),"〇") -> 〇郷 〇佑 | C10: ホンゴウ マユウ | D10: =SUBSTITUTE(REPLACE(C10,1,1,"〇"),MID(C10,LEN(C10)-1,1),"〇") -> 〇ンゴウ マ〇ウ | E10: 認定済 | F10: 272070 | G10: 高槻市 | H10: 8551024469 | I10: 45096 | J10: 45474 | K10: 45838 | L10: 本郷 駿匠 | M10: =SUBSTITUTE(REPLACE(L10,1,1,"〇"),MID(L10,LEN(L10)-1,1),"〇") -> 〇郷 〇匠 | N10: ホンゴウ シュンタ | O10: =SUBSTITUTE(REPLACE(N10,1,1,"〇"),MID(N10,LEN(N10)-1,1),"〇") -> 〇〇ゴウ シュ〇タ | P10: 男 | Q10: 39946 | R10: 45108 | S10: 対象外 | T10: 対象 | U10: 対象外 | V10: 対象外 | W10: 1 | X10: 0 | Z10: 放課後等デイサービス（重症心身障害児以外） | AA10: 18 | AB10: 45474 | AD10: 放課後等デイサービス きららステム西冠 | AE10: 放課後等デイサービス（重症心身障害児以外） | AF10: 5 | AG10: 45474 | AI10: 相談支援事業所すずらん
A11: 増尾 智宏 | B11: =SUBSTITUTE(REPLACE(A11,1,1,"〇"),MID(A11,LEN(A11)-1,1),"〇") -> 〇尾 〇宏 | C11: マスオ トモヒロ | D11: =SUBSTITUTE(REPLACE(C11,1,1,"〇"),MID(C11,LEN(C11)-1,1),"〇") -> 〇スオ トモ〇ロ | E11: 認定済 | F11: 272070 | G11: 高槻市 | H11: 8551011664 | I11: 45098 | J11: 45474 | K11: 45838 | L11: 増尾 颯斗 | M11: =SUBSTITUTE(REPLACE(L11,1,1,"〇"),MID(L11,LEN(L11)-1,1),"〇") -> 〇尾 〇斗 | N11: マスオ ハヤト | O11: =SUBSTITUTE(REPLACE(N11,1,1,"〇"),MID(N11,LEN(N11)-1,1),"〇") -> 〇スオ ハ〇ト | P11: 男 | Q11: 40675 | R11: 43887 | S11: 対象外 | T11: 対象外 | U11: 対象外 | V11: 対象外 | W11: 1 | X11: 4600 | Y11: 放課後等デイサービス きららステム西冠 | Z11: 放課後等デイサービス（重症心身障害児以外） | AA11: 10 | AB11: 45474 | AD11: 放課後等デイサービス きららステム西冠 | AE11: 放課後等デイサービス（重症心身障害児以外） | AF11: 5 | AG11: 45474 | AI11: こども相談支援センターwish
A12: 松田 みずほ | B12: =SUBSTITUTE(REPLACE(A12,1,1,"〇"),MID(A12,LEN(A12)-1,1),"〇") -> 〇田 み〇ほ | C12: マツダ ミズホ | D12: =SUBSTITUTE(REPLACE(C12,1,1,"〇"),MID(C12,LEN(C12)-1,1),"〇") -> 〇ツダ ミ〇ホ | E12: 認定済 | F12: 272070 | G12: 高槻市 | H12: 8551022505 | J12: 45474 | K12: 45838 | L12: 松田 悠希 | M12: =SUBSTITUTE(REPLACE(L12,1,1,"〇"),MID(L12,LEN(L12)-1,1),"〇") -> 〇田 〇希 | N12: マツダ ユウキ | O12: =SUBSTITUTE(REPLACE(N12,1,1,"〇"),MID(N12,LEN(N12)-1,1),"〇") -> 〇ツダ ユ〇キ | P12: 男 | Q12: 41053 | R12: 45748 | S12: 対象外 | T12: 対象外 | U12: 対象外 | V12: 対象外 | W12: 1 | X12: 4600 | Z12: 放課後等デイサービス（重症心身障害児以外） | AA12: 10 | AB12: 45474 | AD12: 放課後等デイサービス きららステム西冠 | AE12: 放課後等デイサービス（重症心身障害児以外） | AF12: 5 | AG12: 45725
A13: 山本 木綿子 | B13: =SUBSTITUTE(REPLACE(A13,1,1,"〇"),MID(A13,LEN(A13)-1,1),"〇") -> 〇本 木〇子 | C13: ヤマモト ユウコ | D13: =SUBSTITUTE(REPLACE(C13,1,1,"〇"),MID(C13,LEN(C13)-1,1),"〇") -> 〇マモト ユ〇コ | E13: 認定済 | F13: 272070 | G13: 高槻市 | H13: 8551024170 | J13: 45474 | K13: 45838 | L13: 山本 佑成 | M13: =SUBSTITUTE(REPLACE(L13,1,1,"〇"),MID(L13,LEN(L13)-1,1),"〇") -> 〇本 〇成 | N13: ヤマモト ユウセイ | O13: =SUBSTITUTE(REPLACE(N13,1,1,"〇"),MID(N13,LEN(N13)-1,1),"〇") -> 〇マモト ユウ〇イ | P13: 男 | Q13: 42137 | R13: 44639 | S13: 対象外 | T13: 対象外 | U13: 対象外 | V13: 対象外 | W13: 1 | X13: 4600 | Y13: 放課後等デイサービス きららステム西冠 | Z13: 放課後等デイサービス（重症心身障害児以外） | AA13: 14 | AB13: 45474 | AD13: 放課後等デイサービス きららステム西冠 | AE13: 放課後等デイサービス（重症心身障害児以外） | AF13: 5 | AG13: 45474 | AI13: こども相談支援センターwish
A14: 大矢 博美 | B14: =SUBSTITUTE(REPLACE(A14,1,1,"〇"),MID(A14,LEN(A14)-1,1),"〇") -> 〇矢 〇美 | C14: オオヤ ヒロミ | D14: =SUBSTITUTE(REPLACE(C14,1,1,"〇"),MID(C14,LEN(C14)-1,1),"〇") -> 〇オヤ ヒ〇ミ | E14: 認定済 | F14: 272070 | G14: 高槻市 | H14: 8551056057 | I14: 45120 | J14: 45505 | K14: 45869 | L14: 大矢 莉穂 | M14: =SUBSTITUTE(REPLACE(L14,1,1,"〇"),MID(L14,LEN(L14)-1,1),"〇") -> 〇矢 〇穂 | N14: オオヤ リホ | O14: =SUBSTITUTE(REPLACE(N14,1,1,"〇"),MID(N14,LEN(N14)-1,1),"〇") -> 〇オヤ 〇ホ | P14: 女 | Q14: 41815 | R14: 44713 | S14: 対象外 | T14: 対象外 | U14: 対象外 | V14: 対象外 | W14: 1 | X14: 4600 | Y14: 放課後等デイサービス きららステム西冠 | Z14: 放課後等デイサービス（重症心身障害児以外） | AA14: 14 | AB14: 45505 | AD14: 放課後等デイサービス きららステム西冠 | AE14: 放課後等デイサービス（重症心身障害児以外） | AF14: 10 | AG14: 45505
A15: 川上 春菜 | B15: =SUBSTITUTE(REPLACE(A15,1,1,"〇"),MID(A15,LEN(A15)-1,1),"〇") -> 〇上 〇菜 | C15: カワカミ ハルナ | D15: =SUBSTITUTE(REPLACE(C15,1,1,"〇"),MID(C15,LEN(C15)-1,1),"〇") -> 〇ワカミ ハ〇ナ | E15: 認定済 | F15: 272070 | G15: 高槻市 | H15: 8551020822 | J15: 45505 | K15: 45869 | L15: 川上 遼太 | M15: =SUBSTITUTE(REPLACE(L15,1,1,"〇"),MID(L15,LEN(L15)-1,1),"〇") -> 〇上 〇太 | N15: カワカミ リョウタ | O15: =SUBSTITUTE(REPLACE(N15,1,1,"〇"),MID(N15,LEN(N15)-1,1),"〇") -> 〇ワカミ リョ〇タ | P15: 男 | Q15: 41817 | R15: 44899 | S15: 対象外 | T15: 対象 | U15: 対象外 | V15: 対象外 | W15: 1 | X15: 37200 | Z15: 放課後等デイサービス（重症心身障害児以外） | AA15: 14 | AB15: 45505 | AD15: 放課後等デイサービス きららステム西冠 | AE15: 放課後等デイサービス（重症心身障害児以外） | AF15: 5 | AG15: 45505 | AI15: 聖ヨハネ子どもセンター
A16: 川元 美穂 | B16: =SUBSTITUTE(REPLACE(A16,1,1,"〇"),MID(A16,LEN(A16)-1,1),"〇") -> 〇元 〇穂 | C16: カワモト ミホ | D16: =SUBSTITUTE(REPLACE(C16,1,1,"〇"),MID(C16,LEN(C16)-1,1),"〇") -> 〇ワモト 〇ホ | E16: 認定済 | F16: 272070 | G16: 高槻市 | H16: 8551018982 | J16: 45505 | K16: 45869 | L16: 川元 舜太 | M16: =SUBSTITUTE(REPLACE(L16,1,1,"〇"),MID(L16,LEN(L16)-1,1),"〇") -> 〇元 〇太 | N16: カワモト シュンタ | O16: =SUBSTITUTE(REPLACE(N16,1,1,"〇"),MID(N16,LEN(N16)-1,1),"〇") -> 〇ワモト シュ〇タ | P16: 男 | Q16: 41813 | R16: 45748 | S16: 対象外 | T16: 対象 | U16: 対象外 | V16: 対象外 | W16: 1 | X16: 4600 | Y16: 放課後等デイサービス きららステム西冠 | Z16: 放課後等デイサービス（重症心身障害児以外） | AA16: 14 | AB16: 45505 | AD16: 放課後等デイサービス きららステム西冠 | AE16: 放課後等デイサービス（重症心身障害児以外） | AF16: 5 | AG16: 45725 | AI16: 相談支援事業所すずらん
A17: 寺迫 愛 | B17: =SUBSTITUTE(REPLACE(A17,1,1,"〇"),MID(A17,LEN(A17)-1,1),"〇") -> 〇迫〇愛 | C17: テラサコ アイ | D17: =SUBSTITUTE(REPLACE(C17,1,1,"〇"),MID(C17,LEN(C17)-1,1),"〇") -> 〇ラサコ 〇イ | E17: 認定済 | F17: 272070 | G17: 高槻市 | H17: 8551025862 | I17: 45120 | J17: 45505 | K17: 45869 | L17: 寺迫 紡 | M17: =SUBSTITUTE(REPLACE(L17,1,1,"〇"),MID(L17,LEN(L17)-1,1),"〇") -> 〇迫〇紡 | N17: テラサコ ツムグ | O17: =SUBSTITUTE(REPLACE(N17,1,1,"〇"),MID(N17,LEN(N17)-1,1),"〇") -> 〇ラサコ ツ〇グ | P17: 男 | Q17: 42179 | R17: 45017 | S17: 対象外 | T17: 対象外 | U17: 対象外 | V17: 対象外 | W17: 1 | X17: 4600 | Y17: 放課後等デイサービス きららステム西冠 | Z17: 放課後等デイサービス（重症心身障害児以外） | AA17: 10 | AB17: 45505 | AD17: 放課後等デイサービス きららステム西冠 | AE17: 放課後等デイサービス（重症心身障害児以外） | AF17: 5 | AG17: 45505
A18: 樋口 広美 | B18: =SUBSTITUTE(REPLACE(A18,1,1,"〇"),MID(A18,LEN(A18)-1,1),"〇") -> 〇口 〇美 | C18: ヒグチ ヒロミ | D18: =SUBSTITUTE(REPLACE(C18,1,1,"〇"),MID(C18,LEN(C18)-1,1),"〇") -> 〇グチ ヒ〇ミ | E18: 認定済 | F18: 272070 | G18: 高槻市 | H18: 8551025623 | J18: 45505 | K18: 45869 | L18: 樋口 瑛己 | M18: =SUBSTITUTE(REPLACE(L18,1,1,"〇"),MID(L18,LEN(L18)-1,1),"〇") -> 〇口 〇己 | N18: ヒグチ エイキ | O18: =SUBSTITUTE(REPLACE(N18,1,1,"〇"),MID(N18,LEN(N18)-1,1),"〇") -> 〇グチ エ〇キ | P18: 男 | Q18: 42529 | R18: 45567 | S18: 対象外 | T18: 対象外 | U18: 対象外 | V18: 対象外 | W18: 1 | X18: 37200 | Z18: 放課後等デイサービス（重症心身障害児以外） | AA18: 10 | AB18: 45505 | AC18: 45869 | AD18: 放課後等デイサービス きららステム西冠 | AE18: 放課後等デイサービス（重症心身障害児以外） | AF18: 4 | AG18: 45560 | AH18: 45869
A19: 村山 智美 | B19: =SUBSTITUTE(REPLACE(A19,1,1,"〇"),MID(A19,LEN(A19)-1,1),"〇") -> 〇山 〇美 | C19: ムラヤマ トモミ | D19: =SUBSTITUTE(REPLACE(C19,1,1,"〇"),MID(C19,LEN(C19)-1,1),"〇") -> 〇ラヤマ ト〇ミ | E19: 認定済 | F19: 272070 | G19: 高槻市 | H19: 8551034005 | I19: 45138 | J19: 45505 | K19: 45869 | L19: 村山 海渡 | M19: =SUBSTITUTE(REPLACE(L19,1,1,"〇"),MID(L19,LEN(L19)-1,1),"〇") -> 〇山 〇渡 | N19: ムラヤマ カイト | O19: =SUBSTITUTE(REPLACE(N19,1,1,"〇"),MID(N19,LEN(N19)-1,1),"〇") -> 〇ラヤマ カ〇ト | P19: 男 | Q19: 42548 | R19: 44996 | S19: 対象外 | T19: 対象外 | U19: 対象外 | V19: 対象外 | W19: 1 | X19: 4600 | Y19: 放課後等デイサービス きららステム西冠 | Z19: 放課後等デイサービス（重症心身障害児以外） | AA19: 10 | AB19: 45505 | AD19: 放課後等デイサービス きららステム西冠 | AE19: 放課後等デイサービス（重症心身障害児以外） | AF19: 5 | AG19: 45505
A20: 山口 久恵 | B20: =SUBSTITUTE(REPLACE(A20,1,1,"〇"),MID(A20,LEN(A20)-1,1),"〇") -> 〇口 〇恵 | C20: ヤマクチ ヒサエ | D20: =SUBSTITUTE(REPLACE(C20,1,1,"〇"),MID(C20,LEN(C20)-1,1),"〇") -> 〇マクチ ヒ〇エ | E20: 認定済 | F20: 272070 | G20: 高槻市 | H20: 8551052338 | J20: 45505 | K20: 45869 | L20: 山口 岳 | M20: =SUBSTITUTE(REPLACE(L20,1,1,"〇"),MID(L20,LEN(L20)-1,1),"〇") -> 〇口〇岳 | N20: ヤマクチ ガク | O20: =SUBSTITUTE(REPLACE(N20,1,1,"〇"),MID(N20,LEN(N20)-1,1),"〇") -> 〇マクチ 〇ク | P20: 男 | Q20: 42178 | R20: 45748 | S20: 対象外 | T20: 対象外 | U20: 対象外 | V20: 対象外 | W20: 1 | X20: 4600 | Y20: 放課後等デイサービス きららステム西冠 | Z20: 放課後等デイサービス（重症心身障害児以外） | AA20: 10 | AB20: 45505 | AD20: 放課後等デイサービス きららステム西冠 | AE20: 放課後等デイサービス（重症心身障害児以外） | AF20: 5 | AG20: 45505
A21: 藤本 祐太 | B21: =SUBSTITUTE(REPLACE(A21,1,1,"〇"),MID(A21,LEN(A21)-1,1),"〇") -> 〇本 〇太 | C21: フジモト ユウタ | D21: =SUBSTITUTE(REPLACE(C21,1,1,"〇"),MID(C21,LEN(C21)-1,1),"〇") -> 〇ジモト ユ〇タ | E21: 認定済 | F21: 272112 | G21: 茨木市 | H21: 5000032598 | I21: 45135 | J21: 45536 | K21: 45869 | L21: 藤本 悠希 | M21: =SUBSTITUTE(REPLACE(L21,1,1,"〇"),MID(L21,LEN(L21)-1,1),"〇") -> 〇本 〇希 | N21: フジモト ユウキ | O21: =SUBSTITUTE(REPLACE(N21,1,1,"〇"),MID(N21,LEN(N21)-1,1),"〇") -> 〇ジモト ユ〇キ | P21: 男 | Q21: 42206 | R21: 44779 | S21: 対象外 | T21: 対象 | U21: 対象外 | V21: 対象外 | W21: 1 | X21: 4600 | Y21: なないろStudy | Z21: 放課後等デイサービス（重症心身障害児以外） | AA21: 10 | AB21: 45536 | AD21: 放課後等デイサービス きららステム西冠 | AE21: 放課後等デイサービス（重症心身障害児以外） | AF21: 2 | AG21: 45536
A22: 井上 拓巳 | B22: =SUBSTITUTE(REPLACE(A22,1,1,"〇"),MID(A22,LEN(A22)-1,1),"〇") -> 〇上 〇巳 | C22: イノウエ タクミ | D22: =SUBSTITUTE(REPLACE(C22,1,1,"〇"),MID(C22,LEN(C22)-1,1),"〇") -> 〇ノウエ タ〇ミ | E22: 認定済 | F22: 272070 | G22: 高槻市 | H22: 8551033858 | J22: 45536 | K22: 45900 | L22: 井上 蒼介 | M22: =SUBSTITUTE(REPLACE(L22,1,1,"〇"),MID(L22,LEN(L22)-1,1),"〇") -> 〇上 〇介 | N22: イノウエ ソウスケ | O22: =SUBSTITUTE(REPLACE(N22,1,1,"〇"),MID(N22,LEN(N22)-1,1),"〇") -> 〇ノウエ ソウ〇ケ | P22: 男 | Q22: 40738 | R22: 45748 | S22: 対象外 | T22: 対象外 | U22: 対象外 | V22: 対象外 | W22: 1 | X22: 4600 | Z22: 放課後等デイサービス（重症心身障害児以外） | AA22: 10 | AB22: 45536 | AD22: 放課後等デイサービス きららステム西冠 | AE22: 放課後等デイサービス（重症心身障害児以外） | AF22: 5 | AG22: 45725
A23: 大内 由香 | B23: =SUBSTITUTE(REPLACE(A23,1,1,"〇"),MID(A23,LEN(A23)-1,1),"〇") -> 〇内 〇香 | C23: オオウチ ユカ | D23: =SUBSTITUTE(REPLACE(C23,1,1,"〇"),MID(C23,LEN(C23)-1,1),"〇") -> 〇オウチ 〇カ | E23: 認定済 | F23: 272070 | G23: 高槻市 | H23: 8551028445 | J23: 45536 | K23: 45900 | L23: 大内 博登 | M23: =SUBSTITUTE(REPLACE(L23,1,1,"〇"),MID(L23,LEN(L23)-1,1),"〇") -> 〇内 〇登 | N23: オオウチ ヒロト | O23: =SUBSTITUTE(REPLACE(N23,1,1,"〇"),MID(N23,LEN(N23)-1,1),"〇") -> 〇オウチ ヒ〇ト | P23: 男 | Q23: 42201 | R23: 45748 | S23: 対象外 | T23: 対象外 | U23: 対象外 | V23: 対象外 | W23: 1 | X23: 37200 | Z23: 放課後等デイサービス（重症心身障害児以外） | AA23: 10 | AB23: 45536 | AC23: 45900 | AD23: 放課後等デイサービス きららステム西冠 | AE23: 放課後等デイサービス（重症心身障害児以外） | AF23: 5 | AG23: 45536 | AH23: 45900
A24: 沖田 亜梨沙 | B24: =SUBSTITUTE(REPLACE(A24,1,1,"〇"),MID(A24,LEN(A24)-1,1),"〇") -> 〇田 亜〇沙 | C24: オキタ アリサ | D24: =SUBSTITUTE(REPLACE(C24,1,1,"〇"),MID(C24,LEN(C24)-1,1),"〇") -> 〇キタ ア〇サ | E24: 認定済 | F24: 272070 | G24: 高槻市 | H24: 8551004636 | I24: 45156 | J24: 45536 | K24: 45900 | L24: 沖田 蒼真 | M24: =SUBSTITUTE(REPLACE(L24,1,1,"〇"),MID(L24,LEN(L24)-1,1),"〇") -> 〇田 〇真 | N24: オキタ ソウマ | O24: =SUBSTITUTE(REPLACE(N24,1,1,"〇"),MID(N24,LEN(N24)-1,1),"〇") -> 〇キタ ソ〇マ | P24: 男 | Q24: 39652 | R24: 45170 | S24: 対象外 | T24: 対象 | U24: 対象外 | V24: 対象外 | W24: 1 | X24: 4600 | Y24: 放課後等デイサービス きららステム西冠 | Z24: 放課後等デイサービス（重症心身障害児以外） | AA24: 23 | AB24: 45536 | AD24: 放課後等デイサービス きららステム西冠 | AE24: 放課後等デイサービス（重症心身障害児以外） | AF24: 5 | AG24: 45536 | AI24: 相談支援事業所おれんじ
A25: 神農 真由子 | B25: =SUBSTITUTE(REPLACE(A25,1,1,"〇"),MID(A25,LEN(A25)-1,1),"〇") -> 〇農 真〇子 | C25: カンノ マユコ | D25: =SUBSTITUTE(REPLACE(C25,1,1,"〇"),MID(C25,LEN(C25)-1,1),"〇") -> 〇ンノ マ〇コ | E25: 認定済 | F25: 272070 | G25: 高槻市 | H25: 8551062253 | J25: 45536 | K25: 45900 | L25: 神農 叶芽 | M25: =SUBSTITUTE(REPLACE(L25,1,1,"〇"),MID(L25,LEN(L25)-1,1),"〇") -> 〇農 〇芽 | N25: カンノ カナメ | O25: =SUBSTITUTE(REPLACE(N25,1,1,"〇"),MID(N25,LEN(N25)-1,1),"〇") -> 〇ンノ カ〇メ | P25: 男 | Q25: 42208 | R25: 45748 | S25: 対象外 | T25: 対象 | U25: 対象外 | V25: 対象外 | W25: 1 | X25: 4600 | Z25: 放課後等デイサービス（重症心身障害児以外） | AA25: 14 | AB25: 45536 | AD25: 放課後等デイサービス きららステム西冠 | AE25: 放課後等デイサービス（重症心身障害児以外） | AF25: 5 | AG25: 45725
A26: 河野 美貴子 | B26: =SUBSTITUTE(REPLACE(A26,1,1,"〇"),MID(A26,LEN(A26)-1,1),"〇") -> 〇野 美〇子 | C26: コウノ ミキコ | D26: =SUBSTITUTE(REPLACE(C26,1,1,"〇"),MID(C26,LEN(C26)-1,1),"〇") -> 〇ウノ ミ〇コ | E26: 認定済 | F26: 272070 | G26: 高槻市 | H26: 8551066601 | I26: 45478 | J26: 45536 | K26: 45900 | L26: 河野 圭悟 | M26: =SUBSTITUTE(REPLACE(L26,1,1,"〇"),MID(L26,LEN(L26)-1,1),"〇") -> 〇野 〇悟 | N26: コウノ ケイゴ | O26: =SUBSTITUTE(REPLACE(N26,1,1,"〇"),MID(N26,LEN(N26)-1,1),"〇") -> 〇ウノ ケ〇ゴ | P26: 男 | Q26: 42216 | R26: 45489 | S26: 対象外 | T26: 対象外 | U26: 対象外 | V26: 対象外 | W26: 1 | X26: 37200 | Z26: 放課後等デイサービス（重症心身障害児以外） | AA26: 10 | AB26: 45536 | AD26: 放課後等デイサービス きららステム西冠 | AE26: 放課後等デイサービス（重症心身障害児以外） | AF26: 5 | AG26: 45536
A27: 野﨑 賜 | B27: =SUBSTITUTE(REPLACE(A27,1,1,"〇"),MID(A27,LEN(A27)-1,1),"〇") -> 〇﨑〇賜 | C27: ノザキ メグム | D27: =SUBSTITUTE(REPLACE(C27,1,1,"〇"),MID(C27,LEN(C27)-1,1),"〇") -> 〇ザキ メ〇ム | E27: 認定済 | F27: 272070 | G27: 高槻市 | H27: 8551059853 | I27: 45383 | J27: 45536 | K27: 45900 | L27: 野﨑 瑞 | M27: =SUBSTITUTE(REPLACE(L27,1,1,"〇"),MID(L27,LEN(L27)-1,1),"〇") -> 〇﨑〇瑞 | N27: ノザキ スイ | O27: =SUBSTITUTE(REPLACE(N27,1,1,"〇"),MID(N27,LEN(N27)-1,1),"〇") -> 〇ザキ 〇イ | P27: 男 | Q27: 42945 | R27: 45383 | S27: 対象外 | T27: 対象外 | U27: 対象外 | V27: 対象外 | W27: 1 | X27: 4600 | Y27: 放課後等デイサービス きららステム西冠 | Z27: 放課後等デイサービス（重症心身障害児以外） | AA27: 10 | AB27: 45536 | AD27: 放課後等デイサービス きららステム西冠 | AE27: 放課後等デイサービス（重症心身障害児以外） | AF27: 5 | AG27: 45536
A28: 森本 響子 | B28: =SUBSTITUTE(REPLACE(A28,1,1,"〇"),MID(A28,LEN(A28)-1,1),"〇") -> 〇本 〇子 | C28: モリモト キョウコ | D28: =SUBSTITUTE(REPLACE(C28,1,1,"〇"),MID(C28,LEN(C28)-1,1),"〇") -> 〇リモト キョ〇コ | E28: 認定済 | F28: 272070 | G28: 高槻市 | H28: 8551028254 | J28: 45536 | K28: 45900 | L28: 森本 凱翔 | M28: =SUBSTITUTE(REPLACE(L28,1,1,"〇"),MID(L28,LEN(L28)-1,1),"〇") -> 〇本 〇翔 | N28: モリモト ヨシト | O28: =SUBSTITUTE(REPLACE(N28,1,1,"〇"),MID(N28,LEN(N28)-1,1),"〇") -> 〇リモト ヨ〇ト | P28: 男 | Q28: 41837 | R28: 45748 | S28: 対象外 | T28: 対象外 | U28: 対象外 | V28: 対象外 | W28: 1 | X28: 4600 | Y28: 放課後等デイサービス きららステム西冠 | Z28: 放課後等デイサービス（重症心身障害児以外） | AA28: 10 | AB28: 45536 | AD28: 放課後等デイサービス きららステム西冠 | AE28: 放課後等デイサービス（重症心身障害児以外） | AF28: 5 | AG28: 45725
A29: 渡邉 智香子 | B29: =SUBSTITUTE(REPLACE(A29,1,1,"〇"),MID(A29,LEN(A29)-1,1),"〇") -> 〇邉 智〇子 | C29: ワタナベ チカコ | D29: =SUBSTITUTE(REPLACE(C29,1,1,"〇"),MID(C29,LEN(C29)-1,1),"〇") -> 〇タナベ チ〇コ | E29: 認定済 | F29: 272070 | G29: 高槻市 | H29: 8551013009 | J29: 45536 | K29: 45900 | L29: 渡邉 尊 | M29: =SUBSTITUTE(REPLACE(L29,1,1,"〇"),MID(L29,LEN(L29)-1,1),"〇") -> 〇邉〇尊 | N29: ワタナベ タケル | O29: =SUBSTITUTE(REPLACE(N29,1,1,"〇"),MID(N29,LEN(N29)-1,1),"〇") -> 〇タナベ タ〇ル | P29: 男 | Q29: 41458 | R29: 43936 | S29: 対象外 | T29: 対象外 | U29: 対象外 | V29: 対象外 | W29: 1 | X29: 4600 | Y29: 放課後等デイサービス きららステム西冠 | Z29: 放課後等デイサービス（重症心身障害児以外） | AA29: 14 | AB29: 45536 | AD29: 放課後等デイサービス きららステム西冠 | AE29: 放課後等デイサービス（重症心身障害児以外） | AF29: 4 | AG29: 45536 | AI29: 聖ヨハネ子どもセンター
A30: 村野 博信 | B30: =SUBSTITUTE(REPLACE(A30,1,1,"〇"),MID(A30,LEN(A30)-1,1),"〇") -> 〇野 〇信 | C30: ムラノ ヒロノブ | D30: =SUBSTITUTE(REPLACE(C30,1,1,"〇"),MID(C30,LEN(C30)-1,1),"〇") -> 〇ラ〇 ヒロ〇ブ | E30: 認定済 | F30: 272070 | G30: 高槻市 | H30: 8551002879 | I30: 45555 | J30: 45566 | K30: 45747 | L30: 村野 智紀 | M30: =SUBSTITUTE(REPLACE(L30,1,1,"〇"),MID(L30,LEN(L30)-1,1),"〇") -> 〇野 〇紀 | N30: ムラノ トモキ | O30: =SUBSTITUTE(REPLACE(N30,1,1,"〇"),MID(N30,LEN(N30)-1,1),"〇") -> 〇ラノ ト〇キ | P30: 男 | Q30: 38941 | R30: 44007 | S30: 対象外 | T30: 対象外 | U30: 対象外 | V30: 対象外 | W30: 1 | X30: 4600 | Z30: 放課後等デイサービス（重症心身障害児以外） | AA30: 10 | AB30: 45566 | AD30: 放課後等デイサービス きららステム西冠 | AE30: 放課後等デイサービス（重症心身障害児以外） | AF30: 5 | AG30: 45566
A31: 秋山 文子 | B31: =SUBSTITUTE(REPLACE(A31,1,1,"〇"),MID(A31,LEN(A31)-1,1),"〇") -> 〇山 〇子 | C31: アキヤマ フミコ | D31: =SUBSTITUTE(REPLACE(C31,1,1,"〇"),MID(C31,LEN(C31)-1,1),"〇") -> 〇キヤマ フ〇コ | E31: 認定済 | F31: 272070 | G31: 高槻市 | H31: 8551013686 | I31: 45560 | J31: 45566 | K31: 45930 | L31: 秋山 快翔 | M31: =SUBSTITUTE(REPLACE(L31,1,1,"〇"),MID(L31,LEN(L31)-1,1),"〇") -> 〇山 〇翔 | N31: アキヤマ カイト | O31: =SUBSTITUTE(REPLACE(N31,1,1,"〇"),MID(N31,LEN(N31)-1,1),"〇") -> 〇キヤマ カ〇ト | P31: 男 | Q31: 41490 | R31: 44323 | S31: 対象外 | T31: 対象外 | U31: 対象外 | V31: 対象外 | W31: 1 | X31: 37200 | Z31: 放課後等デイサービス（重症心身障害児以外） | AA31: 18 | AB31: 45566 | AD31: 放課後等デイサービス きららステム西冠 | AE31: 放課後等デイサービス（重症心身障害児以外） | AF31: 1 | AG31: 45566 | AI31: 相談支援室おひさま＋
A32: 熱田 薫 | B32: =SUBSTITUTE(REPLACE(A32,1,1,"〇"),MID(A32,LEN(A32)-1,1),"〇") -> 〇田〇薫 | C32: アツタ カオル | D32: =SUBSTITUTE(REPLACE(C32,1,1,"〇"),MID(C32,LEN(C32)-1,1),"〇") -> 〇ツタ カ〇ル | E32: 認定済 | F32: 272070 | G32: 高槻市 | H32: 8551008561 | I32: 45546 | J32: 45566 | K32: 45930 | L32: 熱田 波音 | M32: =SUBSTITUTE(REPLACE(L32,1,1,"〇"),MID(L32,LEN(L32)-1,1),"〇") -> 〇田 〇音 | N32: アツタ ハルト | O32: =SUBSTITUTE(REPLACE(N32,1,1,"〇"),MID(N32,LEN(N32)-1,1),"〇") -> 〇ツタ ハ〇ト | P32: 男 | Q32: 40407 | R32: 45200 | S32: 対象外 | T32: 対象外 | U32: 対象外 | V32: 対象外 | W32: 1 | X32: 0 | Z32: 放課後等デイサービス（重症心身障害児以外） | AA32: 14 | AB32: 45566 | AD32: 放課後等デイサービス きららステム西冠 | AE32: 放課後等デイサービス（重症心身障害児以外） | AF32: 14 | AG32: 45566
A33: 網野 郁絵 | B33: =SUBSTITUTE(REPLACE(A33,1,1,"〇"),MID(A33,LEN(A33)-1,1),"〇") -> 〇野 〇絵 | C33: アミノ イクエ | D33: =SUBSTITUTE(REPLACE(C33,1,1,"〇"),MID(C33,LEN(C33)-1,1),"〇") -> 〇ミノ イ〇エ | E33: 認定済 | F33: 272070 | G33: 高槻市 | H33: 8551013389 | J33: 45566 | K33: 45930 | L33: 網野 晴 | M33: =SUBSTITUTE(REPLACE(L33,1,1,"〇"),MID(L33,LEN(L33)-1,1),"〇") -> 〇野〇晴 | N33: アミノ ハル | O33: =SUBSTITUTE(REPLACE(N33,1,1,"〇"),MID(N33,LEN(N33)-1,1),"〇") -> 〇ミノ 〇ル | P33: 男 | Q33: 41135 | R33: 45748 | S33: 対象外 | T33: 対象外 | U33: 対象外 | V33: 対象外 | W33: 1 | X33: 4600 | Z33: 放課後等デイサービス（重症心身障害児以外） | AA33: 10 | AB33: 45566 | AD33: 放課後等デイサービス きららステム西冠 | AE33: 放課後等デイサービス（重症心身障害児以外） | AF33: 5 | AG33: 45725 | AI33: 相談支援 チェリー・ハート
A34: 家里 夏子 | B34: =SUBSTITUTE(REPLACE(A34,1,1,"〇"),MID(A34,LEN(A34)-1,1),"〇") -> 〇里 〇子 | C34: イエサト ナツコ | D34: =SUBSTITUTE(REPLACE(C34,1,1,"〇"),MID(C34,LEN(C34)-1,1),"〇") -> 〇エサト ナ〇コ | E34: 認定済 | F34: 272070 | G34: 高槻市 | H34: 8551020749 | J34: 45566 | K34: 45930 | L34: 家里 義史 | M34: =SUBSTITUTE(REPLACE(L34,1,1,"〇"),MID(L34,LEN(L34)-1,1),"〇") -> 〇里 〇史 | N34: イエサト ヨシフミ | O34: =SUBSTITUTE(REPLACE(N34,1,1,"〇"),MID(N34,LEN(N34)-1,1),"〇") -> 〇エサト ヨシ〇ミ | P34: 男 | Q34: 41874 | R34: 45748 | S34: 対象外 | T34: 対象外 | U34: 対象外 | V34: 対象外 | W34: 1 | X34: 4600 | Z34: 放課後等デイサービス（重症心身障害児以外） | AA34: 10 | AB34: 45566 | AD34: 放課後等デイサービス きららステム西冠 | AE34: 放課後等デイサービス（重症心身障害児以外） | AF34: 5 | AG34: 45725 | AI34: 相談支援事業所すずらん
A35: 加藤 亜希子 | B35: =SUBSTITUTE(REPLACE(A35,1,1,"〇"),MID(A35,LEN(A35)-1,1),"〇") -> 〇藤 亜〇子 | C35: カトウ アキコ | D35: =SUBSTITUTE(REPLACE(C35,1,1,"〇"),MID(C35,LEN(C35)-1,1),"〇") -> 〇トウ ア〇コ | E35: 認定済 | F35: 272070 | G35: 高槻市 | H35: 8551052379 | J35: 45566 | K35: 45930 | L35: 加藤 雄人 | M35: =SUBSTITUTE(REPLACE(L35,1,1,"〇"),MID(L35,LEN(L35)-1,1),"〇") -> 〇藤 〇人 | N35: カトウ ユウト | O35: =SUBSTITUTE(REPLACE(N35,1,1,"〇"),MID(N35,LEN(N35)-1,1),"〇") -> 〇ト〇 ユ〇ト | P35: 男 | Q35: 41127 | R35: 45748 | S35: 対象外 | T35: 対象外 | U35: 対象外 | V35: 対象外 | W35: 1 | X35: 4600 | Y35: 放課後等デイサービス きららステム西冠 | Z35: 放課後等デイサービス（重症心身障害児以外） | AA35: 10 | AB35: 45566 | AD35: 放課後等デイサービス きららステム西冠 | AE35: 放課後等デイサービス（重症心身障害児以外） | AF35: 5 | AG35: 45725
A36: 高柳 綾 | B36: =SUBSTITUTE(REPLACE(A36,1,1,"〇"),MID(A36,LEN(A36)-1,1),"〇") -> 〇柳〇綾 | C36: タカヤナギ アヤ | D36: =SUBSTITUTE(REPLACE(C36,1,1,"〇"),MID(C36,LEN(C36)-1,1),"〇") -> 〇カヤナギ 〇ヤ | E36: 認定済 | F36: 272070 | G36: 高槻市 | H36: 8551005401 | I36: 45194 | J36: 45566 | K36: 45930 | L36: 高柳 一輝 | M36: =SUBSTITUTE(REPLACE(L36,1,1,"〇"),MID(L36,LEN(L36)-1,1),"〇") -> 〇柳 〇輝 | N36: タカヤナギ イツキ | O36: =SUBSTITUTE(REPLACE(N36,1,1,"〇"),MID(N36,LEN(N36)-1,1),"〇") -> 〇カヤナギ イ〇キ | P36: 男 | Q36: 40397 | R36: 44310 | S36: 対象外 | T36: 対象 | U36: 対象外 | V36: 対象外 | W36: 1 | X36: 4600 | Z36: 放課後等デイサービス（重症心身障害児以外） | AA36: 14 | AB36: 45566 | AD36: 放課後等デイサービス きららステム西冠 | AE36: 放課後等デイサービス（重症心身障害児以外） | AF36: 4 | AG36: 45566 | AI36: こども相談支援センターwish
A37: 中原 栄子 | B37: =SUBSTITUTE(REPLACE(A37,1,1,"〇"),MID(A37,LEN(A37)-1,1),"〇") -> 〇原 〇子 | C37: ナカハラ エイコ | D37: =SUBSTITUTE(REPLACE(C37,1,1,"〇"),MID(C37,LEN(C37)-1,1),"〇") -> 〇カハラ エ〇コ | E37: 認定済 | F37: 272070 | G37: 高槻市 | H37: 8551019758 | J37: 45566 | K37: 45930 | L37: 中原 蒼十朗 | M37: =SUBSTITUTE(REPLACE(L37,1,1,"〇"),MID(L37,LEN(L37)-1,1),"〇") -> 〇原 蒼〇朗 | N37: ナカハラ ソウジュウロウ | O37: =SUBSTITUTE(REPLACE(N37,1,1,"〇"),MID(N37,LEN(N37)-1,1),"〇") -> 〇カハラ ソウジュウ〇ウ | P37: 男 | Q37: 41875 | R37: 45748 | S37: 対象外 | T37: 対象外 | U37: 対象外 | V37: 対象外 | W37: 1 | X37: 4600 | Z37: 放課後等デイサービス（重症心身障害児以外） | AA37: 10 | AB37: 45566 | AD37: 放課後等デイサービス きららステム西冠 | AE37: 放課後等デイサービス（重症心身障害児以外） | AF37: 5 | AG37: 45725
A38: 藤井 朋世 | B38: =SUBSTITUTE(REPLACE(A38,1,1,"〇"),MID(A38,LEN(A38)-1,1),"〇") -> 〇井 〇世 | C38: フジイ トモヨ | D38: =SUBSTITUTE(REPLACE(C38,1,1,"〇"),MID(C38,LEN(C38)-1,1),"〇") -> 〇ジイ ト〇ヨ | E38: 認定済 | F38: 272070 | G38: 高槻市 | H38: 8551016374 | J38: 45566 | K38: 45930 | L38: 藤井 翔 | M38: =SUBSTITUTE(REPLACE(L38,1,1,"〇"),MID(L38,LEN(L38)-1,1),"〇") -> 〇井〇翔 | N38: フジイ カケル | O38: =SUBSTITUTE(REPLACE(N38,1,1,"〇"),MID(N38,LEN(N38)-1,1),"〇") -> 〇ジイ カ〇ル | P38: 男 | Q38: 41489 | R38: 43986 | S38: 対象外 | T38: 対象外 | U38: 対象外 | V38: 対象外 | W38: 1 | X38: 4600 | Y38: 放課後等デイサービス きららステム西冠 | Z38: 放課後等デイサービス（重症心身障害児以外） | AA38: 10 | AB38: 45566 | AD38: 放課後等デイサービス きららステム西冠 | AE38: 放課後等デイサービス（重症心身障害児以外） | AF38: 4 | AG38: 45566
A39: 藤井 朋世 | B39: =SUBSTITUTE(REPLACE(A39,1,1,"〇"),MID(A39,LEN(A39)-1,1),"〇") -> 〇井 〇世 | C39: フジイ トモヨ | D39: =SUBSTITUTE(REPLACE(C39,1,1,"〇"),MID(C39,LEN(C39)-1,1),"〇") -> 〇ジイ ト〇ヨ | E39: 認定済 | F39: 272070 | G39: 高槻市 | H39: 8551016382 | J39: 45566 | K39: 45930 | L39: 藤井 翼 | M39: =SUBSTITUTE(REPLACE(L39,1,1,"〇"),MID(L39,LEN(L39)-1,1),"〇") -> 〇井〇翼 | N39: フジイ ツバサ | O39: =SUBSTITUTE(REPLACE(N39,1,1,"〇"),MID(N39,LEN(N39)-1,1),"〇") -> 〇ジイ ツ〇サ | P39: 男 | Q39: 41489 | R39: 43986 | S39: 対象外 | T39: 対象外 | U39: 対象外 | V39: 対象外 | W39: 1 | X39: 4600 | Y39: 放課後等デイサービス きららステム西冠 | Z39: 放課後等デイサービス（重症心身障害児以外） | AA39: 10 | AB39: 45566 | AD39: 放課後等デイサービス きららステム西冠 | AE39: 放課後等デイサービス（重症心身障害児以外） | AF39: 4 | AG39: 45566
A40: 松村 珠代 | B40: =SUBSTITUTE(REPLACE(A40,1,1,"〇"),MID(A40,LEN(A40)-1,1),"〇") -> 〇村 〇代 | C40: マツムラ タマヨ | D40: =SUBSTITUTE(REPLACE(C40,1,1,"〇"),MID(C40,LEN(C40)-1,1),"〇") -> 〇ツムラ タ〇ヨ | E40: 認定済 | F40: 272070 | G40: 高槻市 | H40: 8551058061 | I40: 45546 | J40: 45566 | K40: 45930 | L40: 松村 一花 | M40: =SUBSTITUTE(REPLACE(L40,1,1,"〇"),MID(L40,LEN(L40)-1,1),"〇") -> 〇村 〇花 | N40: マツムラ イチカ | O40: =SUBSTITUTE(REPLACE(N40,1,1,"〇"),MID(N40,LEN(N40)-1,1),"〇") -> 〇ツムラ イ〇カ | P40: 女 | Q40: 41504 | R40: 45566 | S40: 対象外 | T40: 対象外 | U40: 対象外 | V40: 対象外 | W40: 1 | X40: 37200 | Z40: 放課後等デイサービス（重症心身障害児以外） | AA40: 10 | AB40: 45566 | AC40: 45930 | AD40: 放課後等デイサービス きららステム西冠 | AE40: 放課後等デイサービス（重症心身障害児以外） | AF40: 4 | AG40: 45566 | AH40: 45930
...

Sheet 利用者情報　一覧(障害)-照会画面
A1: 利用者名 | B1: 利用者名（伏字） | C1: 児童名 | D1: 児童名（伏字） | E1: 生年月日 | F1: 住所(都道府県/市区町村) | G1: 受給者 | H1: 受給者証適用期間 | I1: 電話番号 | J1: 電話番号（伏字） | K1: 利用者
G2: 証番号 | K2: の状態
A3: 高柳 綾 | B3: =SUBSTITUTE(REPLACE(A3,1,1,"〇"),MID(A3,LEN(A3)-1,1),"〇") -> 〇柳〇綾 | C3: 高柳 一輝 | D3: =SUBSTITUTE(REPLACE(C3,1,1,"〇"),MID(C3,LEN(C3)-1,1),"〇") -> 〇柳 〇輝 | E3: 40397 | F3: 大阪府 高槻市 | G3: 8551005401 | H3: 令和6年10月1日から令和7年9月30日まで | I3: 072-671-4854 | J3: =IF(I3<>"",SUBSTITUTE(REPLACE(I3,1,1,"0"),MID(I3,LEN(I3)-1,1),"0"),"") -> 072-671-4804 | K3: 利用中
A4: 武山 明菜 | B4: =SUBSTITUTE(REPLACE(A4,1,1,"〇"),MID(A4,LEN(A4)-1,1),"〇") -> 〇山 〇菜 | C4: 武山 紘太朗 | D4: =SUBSTITUTE(REPLACE(C4,1,1,"〇"),MID(C4,LEN(C4)-1,1),"〇") -> 〇山 紘〇朗 | E4: 40493 | F4: 大阪府 高槻市 | G4: 8551005179 | H4: 令和7年1月1日から令和7年12月31日まで | J4: =IF(I4<>"",SUBSTITUTE(REPLACE(I4,1,1,"0"),MID(I4,LEN(I4)-1,1),"0"),"") | K4: 利用中
A5: 辻 里沙 | B5: =SUBSTITUTE(REPLACE(A5,1,1,"〇"),MID(A5,LEN(A5)-1,1),"〇") -> 〇 〇沙 | C5: 辻 航史朗 | D5: =SUBSTITUTE(REPLACE(C5,1,1,"〇"),MID(C5,LEN(C5)-1,1),"〇") -> 〇 航〇朗 | E5: 41634 | F5: 大阪府 高槻市 | G5: 8551026563 | H5: 令和7年2月1日から令和8年1月31日まで | J5: =IF(I5<>"",SUBSTITUTE(REPLACE(I5,1,1,"0"),MID(I5,LEN(I5)-1,1),"0"),"") | K5: 利用中
A6: 寺迫 愛 | B6: =SUBSTITUTE(REPLACE(A6,1,1,"〇"),MID(A6,LEN(A6)-1,1),"〇") -> 〇迫〇愛 | C6: 寺迫 紡 | D6: =SUBSTITUTE(REPLACE(C6,1,1,"〇"),MID(C6,LEN(C6)-1,1),"〇") -> 〇迫〇紡 | E6: 42179 | F6: 大阪府 高槻市 | G6: 8551025862 | H6: 令和6年8月1日から令和7年7月31日まで | J6: =IF(I6<>"",SUBSTITUTE(REPLACE(I6,1,1,"0"),MID(I6,LEN(I6)-1,1),"0"),"") | K6: 利用中
A7: 寺本 典子 | B7: =SUBSTITUTE(REPLACE(A7,1,1,"〇"),MID(A7,LEN(A7)-1,1),"〇") -> 〇本 〇子 | C7: 寺本 和真 | D7: =SUBSTITUTE(REPLACE(C7,1,1,"〇"),MID(C7,LEN(C7)-1,1),"〇") -> 〇本 〇真 | E7: 39472 | F7: 大阪府 高槻市 | G7: 8551010047 | H7: 令和7年3月1日から令和8年2月28日まで | I7: 072-675-1386 | J7: =IF(I7<>"",SUBSTITUTE(REPLACE(I7,1,1,"0"),MID(I7,LEN(I7)-1,1),"0"),"") -> 072-675-1306 | K7: 利用中
A8: 遠山 路子 | B8: =SUBSTITUTE(REPLACE(A8,1,1,"〇"),MID(A8,LEN(A8)-1,1),"〇") -> 〇山 〇子 | C8: 遠山 桃弥 | D8: =SUBSTITUTE(REPLACE(C8,1,1,"〇"),MID(C8,LEN(C8)-1,1),"〇") -> 〇山 〇弥 | E8: 42429 | F8: 大阪府 高槻市 | G8: 8551026910 | H8: 令和7年4月1日から令和8年3月31日まで | I8: 072-628-8284 | J8: =IF(I8<>"",SUBSTITUTE(REPLACE(I8,1,1,"0"),MID(I8,LEN(I8)-1,1),"0"),"") -> 072-620-0204 | K8: 利用中
A9: 富岡 和子 | B9: =SUBSTITUTE(REPLACE(A9,1,1,"〇"),MID(A9,LEN(A9)-1,1),"〇") -> 〇岡 〇子 | C9: 富岡 響希 | D9: =SUBSTITUTE(REPLACE(C9,1,1,"〇"),MID(C9,LEN(C9)-1,1),"〇") -> 〇岡 〇希 | E9: 41611 | F9: 大阪府 高槻市 | G9: 8551025409 | H9: 令和7年2月1日から令和8年1月31日まで | I9: 072-628-4318 | J9: =IF(I9<>"",SUBSTITUTE(REPLACE(I9,1,1,"0"),MID(I9,LEN(I9)-1,1),"0"),"") -> 072-628-4308 | K9: 利用中
A10: 富岡 和子 | B10: =SUBSTITUTE(REPLACE(A10,1,1,"〇"),MID(A10,LEN(A10)-1,1),"〇") -> 〇岡 〇子 | C10: 富岡 雫 | D10: =SUBSTITUTE(REPLACE(C10,1,1,"〇"),MID(C10,LEN(C10)-1,1),"〇") -> 〇岡〇雫 | E10: 42419 | F10: 大阪府 高槻市 | G10: 8551070207 | H10: 令和7年4月1日から令和8年3月31日まで | I10: 072-628-4318 | J10: =IF(I10<>"",SUBSTITUTE(REPLACE(I10,1,1,"0"),MID(I10,LEN(I10)-1,1),"0"),"") -> 072-628-4308 | K10: 利用中
A11: 土橋 愛 | B11: =SUBSTITUTE(REPLACE(A11,1,1,"〇"),MID(A11,LEN(A11)-1,1),"〇") -> 〇橋〇愛 | C11: 土橋 柚希 | D11: =SUBSTITUTE(REPLACE(C11,1,1,"〇"),MID(C11,LEN(C11)-1,1),"〇") -> 〇橋 〇希 | E11: 42115 | F11: 大阪府 高槻市 | G11: 8551023743 | H11: 令和7年6月1日から令和8年5月31日まで | I11: 072-655-5145 | J11: =IF(I11<>"",SUBSTITUTE(REPLACE(I11,1,1,"0"),MID(I11,LEN(I11)-1,1),"0"),"") -> 072-655-5105 | K11: 利用中
A12: 内藤 有由美 | B12: =SUBSTITUTE(REPLACE(A12,1,1,"〇"),MID(A12,LEN(A12)-1,1),"〇") -> 〇藤 有〇美 | C12: 内藤 聡祐 | D12: =SUBSTITUTE(REPLACE(C12,1,1,"〇"),MID(C12,LEN(C12)-1,1),"〇") -> 〇藤 〇祐 | E12: 41993 | F12: 大阪府 高槻市 | G12: 8551019725 | H12: 令和7年2月1日から令和8年1月31日まで | I12: 072-629-4359 | J12: =IF(I12<>"",SUBSTITUTE(REPLACE(I12,1,1,"0"),MID(I12,LEN(I12)-1,1),"0"),"") -> 072-629-4309 | K12: 利用中
A13: 中西 恵 | B13: =SUBSTITUTE(REPLACE(A13,1,1,"〇"),MID(A13,LEN(A13)-1,1),"〇") -> 〇西〇恵 | C13: 中西 玲偉 | D13: =SUBSTITUTE(REPLACE(C13,1,1,"〇"),MID(C13,LEN(C13)-1,1),"〇") -> 〇西 〇偉 | E13: 42278 | F13: 大阪府 高槻市 | G13: 8551025888 | H13: 令和6年12月1日から令和7年11月30日まで | J13: =IF(I13<>"",SUBSTITUTE(REPLACE(I13,1,1,"0"),MID(I13,LEN(I13)-1,1),"0"),"") | K13: 利用中
A14: 中原 栄子 | B14: =SUBSTITUTE(REPLACE(A14,1,1,"〇"),MID(A14,LEN(A14)-1,1),"〇") -> 〇原 〇子 | C14: 中原 蒼十朗 | D14: =SUBSTITUTE(REPLACE(C14,1,1,"〇"),MID(C14,LEN(C14)-1,1),"〇") -> 〇原 蒼〇朗 | E14: 41875 | F14: 大阪府 高槻市 | G14: 8551019758 | H14: 令和6年10月1日から令和7年9月30日まで | I14: 072-696-6321 | J14: =IF(I14<>"",SUBSTITUTE(REPLACE(I14,1,1,"0"),MID(I14,LEN(I14)-1,1),"0"),"") -> 070-696-6301 | K14: 利用中
A15: 中村 暢子 | B15: =SUBSTITUTE(REPLACE(A15,1,1,"〇"),MID(A15,LEN(A15)-1,1),"〇") -> 〇村 〇子 | C15: 中村 颯人 | D15: =SUBSTITUTE(REPLACE(C15,1,1,"〇"),MID(C15,LEN(C15)-1,1),"〇") -> 〇村 〇人 | E15: 42400 | F15: 大阪府 高槻市 | G15: 8551030060 | H15: 令和7年3月1日から令和8年2月28日まで | I15: 072-6283-395 | J15: =IF(I15<>"",SUBSTITUTE(REPLACE(I15,1,1,"0"),MID(I15,LEN(I15)-1,1),"0"),"") -> 072-6283-305 | K15: 利用中
A16: 中村 友里 | B16: =SUBSTITUTE(REPLACE(A16,1,1,"〇"),MID(A16,LEN(A16)-1,1),"〇") -> 〇村 〇里 | C16: 中村 大輝 | D16: =SUBSTITUTE(REPLACE(C16,1,1,"〇"),MID(C16,LEN(C16)-1,1),"〇") -> 〇村 〇輝 | E16: 39728 | F16: 大阪府 高槻市 | G16: 3100013873 | H16: 令和6年12月1日から令和7年11月30日まで | I16: 080-1463-0817 | J16: =IF(I16<>"",SUBSTITUTE(REPLACE(I16,1,1,"0"),MID(I16,LEN(I16)-1,1),"0"),"") -> 080-0463-0807 | K16: 利用中
A17: 西田 由佳 | B17: =SUBSTITUTE(REPLACE(A17,1,1,"〇"),MID(A17,LEN(A17)-1,1),"〇") -> 〇田 〇佳 | C17: 西田 幸生 | D17: =SUBSTITUTE(REPLACE(C17,1,1,"〇"),MID(C17,LEN(C17)-1,1),"〇") -> 〇田 〇生 | E17: 42450 | F17: 大阪府 高槻市 | G17: 8551064465 | H17: 令和7年5月1日から令和8年4月30日まで | J17: =IF(I17<>"",SUBSTITUTE(REPLACE(I17,1,1,"0"),MID(I17,LEN(I17)-1,1),"0"),"") | K17: 利用中
A18: 服部 愛 | B18: =SUBSTITUTE(REPLACE(A18,1,1,"〇"),MID(A18,LEN(A18)-1,1),"〇") -> 〇部〇愛 | C18: 服部 由侑 | D18: =SUBSTITUTE(REPLACE(C18,1,1,"〇"),MID(C18,LEN(C18)-1,1),"〇") -> 〇部 〇侑 | E18: 42045 | F18: 大阪府 高槻市 | G18: 8551026373 | H18: 令和7年4月1日から令和8年3月31日まで | I18: 072-675-1724 | J18: =IF(I18<>"",SUBSTITUTE(REPLACE(I18,1,1,"0"),MID(I18,LEN(I18)-1,1),"0"),"") -> 070-675-1704 | K18: 利用中
A19: 林 純子 | B19: =SUBSTITUTE(REPLACE(A19,1,1,"〇"),MID(A19,LEN(A19)-1,1),"〇") -> 〇 〇子 | C19: 林 航希 | D19: =SUBSTITUTE(REPLACE(C19,1,1,"〇"),MID(C19,LEN(C19)-1,1),"〇") -> 〇 〇希 | E19: 41609 | F19: 大阪府 高槻市 | G19: 8551022067 | H19: 令和7年2月1日から令和8年1月31日まで | I19: 072-655-1852 | J19: =IF(I19<>"",SUBSTITUTE(REPLACE(I19,1,1,"0"),MID(I19,LEN(I19)-1,1),"0"),"") -> 072-600-1802 | K19: 利用中
A20: 春木 早百合 | B20: =SUBSTITUTE(REPLACE(A20,1,1,"〇"),MID(A20,LEN(A20)-1,1),"〇") -> 〇木 早〇合 | C20: 春木 嶺汰 | D20: =SUBSTITUTE(REPLACE(C20,1,1,"〇"),MID(C20,LEN(C20)-1,1),"〇") -> 〇木 〇汰 | E20: 40485 | F20: 大阪府 高槻市 | G20: 8551013678 | H20: 令和7年1月1日から令和7年12月31日まで | I20: 072-628-8159 | J20: =IF(I20<>"",SUBSTITUTE(REPLACE(I20,1,1,"0"),MID(I20,LEN(I20)-1,1),"0"),"") -> 072-628-8109 | K20: 利用中
A21: 樋口 広美 | B21: =SUBSTITUTE(REPLACE(A21,1,1,"〇"),MID(A21,LEN(A21)-1,1),"〇") -> 〇口 〇美 | C21: 樋口 瑛己 | D21: =SUBSTITUTE(REPLACE(C21,1,1,"〇"),MID(C21,LEN(C21)-1,1),"〇") -> 〇口 〇己 | E21: 42529 | F21: 大阪府 高槻市 | G21: 8551025623 | H21: 令和6年8月1日から令和7年7月31日まで | I21: 072-668-7665 | J21: =IF(I21<>"",SUBSTITUTE(REPLACE(I21,1,1,"0"),MID(I21,LEN(I21)-1,1),"0"),"") -> 072-008-7005 | K21: 利用中
A22: 藤井 朋世 | B22: =SUBSTITUTE(REPLACE(A22,1,1,"〇"),MID(A22,LEN(A22)-1,1),"〇") -> 〇井 〇世 | C22: 藤井 翔 | D22: =SUBSTITUTE(REPLACE(C22,1,1,"〇"),MID(C22,LEN(C22)-1,1),"〇") -> 〇井〇翔 | E22: 41489 | F22: 大阪府 高槻市 | G22: 8551016374 | H22: 令和6年10月1日から令和7年9月30日まで | I22: 072-671-8983 | J22: =IF(I22<>"",SUBSTITUTE(REPLACE(I22,1,1,"0"),MID(I22,LEN(I22)-1,1),"0"),"") -> 072-671-0903 | K22: 利用中
A23: 藤井 朋世 | B23: =SUBSTITUTE(REPLACE(A23,1,1,"〇"),MID(A23,LEN(A23)-1,1),"〇") -> 〇井 〇世 | C23: 藤井 翼 | D23: =SUBSTITUTE(REPLACE(C23,1,1,"〇"),MID(C23,LEN(C23)-1,1),"〇") -> 〇井〇翼 | E23: 41489 | F23: 大阪府 高槻市 | G23: 8551016382 | H23: 令和6年10月1日から令和7年9月30日まで | I23: 072-671-8983 | J23: =IF(I23<>"",SUBSTITUTE(REPLACE(I23,1,1,"0"),MID(I23,LEN(I23)-1,1),"0"),"") -> 072-671-0903 | K23: 利用中
A24: 藤本 恵 | B24: =SUBSTITUTE(REPLACE(A24,1,1,"〇"),MID(A24,LEN(A24)-1,1),"〇") -> 〇本〇恵 | C24: 藤本 聖 | D24: =SUBSTITUTE(REPLACE(C24,1,1,"〇"),MID(C24,LEN(C24)-1,1),"〇") -> 〇本〇聖 | E24: 42082 | F24: 大阪府 高槻市 | G24: 8551019857 | H24: 令和7年5月1日から令和8年4月30日まで | J24: =IF(I24<>"",SUBSTITUTE(REPLACE(I24,1,1,"0"),MID(I24,LEN(I24)-1,1),"0"),"") | K24: 利用中
A25: 藤本 祐太 | B25: =SUBSTITUTE(REPLACE(A25,1,1,"〇"),MID(A25,LEN(A25)-1,1),"〇") -> 〇本 〇太 | C25: 藤本 悠希 | D25: =SUBSTITUTE(REPLACE(C25,1,1,"〇"),MID(C25,LEN(C25)-1,1),"〇") -> 〇本 〇希 | E25: 42206 | F25: 大阪府 茨木市 | G25: 5000032598 | H25: 令和6年9月1日から令和7年7月31日まで | J25: =IF(I25<>"",SUBSTITUTE(REPLACE(I25,1,1,"0"),MID(I25,LEN(I25)-1,1),"0"),"") | K25: 利用中
A26: 本郷 麻佑 | B26: =SUBSTITUTE(REPLACE(A26,1,1,"〇"),MID(A26,LEN(A26)-1,1),"〇") -> 〇郷 〇佑 | C26: 本郷 駿匠 | D26: =SUBSTITUTE(REPLACE(C26,1,1,"〇"),MID(C26,LEN(C26)-1,1),"〇") -> 〇郷 〇匠 | E26: 39946 | F26: 大阪府 高槻市 | G26: 8551024469 | H26: 令和6年7月1日から令和7年6月30日まで | J26: =IF(I26<>"",SUBSTITUTE(REPLACE(I26,1,1,"0"),MID(I26,LEN(I26)-1,1),"0"),"") | K26: 利用中
A27: 本郷 麻佑 | B27: =SUBSTITUTE(REPLACE(A27,1,1,"〇"),MID(A27,LEN(A27)-1,1),"〇") -> 〇郷 〇佑 | C27: 本郷 蔵之介 | D27: =SUBSTITUTE(REPLACE(C27,1,1,"〇"),MID(C27,LEN(C27)-1,1),"〇") -> 〇郷 蔵〇介 | E27: 40537 | F27: 大阪府 高槻市 | G27: 8551024451 | H27: 令和7年2月1日から令和8年1月31日まで | J27: =IF(I27<>"",SUBSTITUTE(REPLACE(I27,1,1,"0"),MID(I27,LEN(I27)-1,1),"0"),"") | K27: 利用中
A28: 増尾 智宏 | B28: =SUBSTITUTE(REPLACE(A28,1,1,"〇"),MID(A28,LEN(A28)-1,1),"〇") -> 〇尾 〇宏 | C28: 増尾 颯斗 | D28: =SUBSTITUTE(REPLACE(C28,1,1,"〇"),MID(C28,LEN(C28)-1,1),"〇") -> 〇尾 〇斗 | E28: 40675 | F28: 大阪府 高槻市 | G28: 8551011664 | H28: 令和6年7月1日から令和7年6月30日まで | I28: 072-661-0177 | J28: =IF(I28<>"",SUBSTITUTE(REPLACE(I28,1,1,"0"),MID(I28,LEN(I28)-1,1),"0"),"") -> 002-661-0100 | K28: 利用中
A29: 松井 幸子 | B29: =SUBSTITUTE(REPLACE(A29,1,1,"〇"),MID(A29,LEN(A29)-1,1),"〇") -> 〇井 〇子 | C29: 松井 亮弥 | D29: =SUBSTITUTE(REPLACE(C29,1,1,"〇"),MID(C29,LEN(C29)-1,1),"〇") -> 〇井 〇弥 | E29: 42324 | F29: 大阪府 高槻市 | G29: 8551024022 | H29: 令和7年1月6日から令和7年12月31日まで | I29: 072-693-4162 | J29: =IF(I29<>"",SUBSTITUTE(REPLACE(I29,1,1,"0"),MID(I29,LEN(I29)-1,1),"0"),"") -> 072-093-4102 | K29: 利用中
A30: 松岡 紀代子 | B30: =SUBSTITUTE(REPLACE(A30,1,1,"〇"),MID(A30,LEN(A30)-1,1),"〇") -> 〇岡 紀〇子 | C30: 松岡 美希 | D30: =SUBSTITUTE(REPLACE(C30,1,1,"〇"),MID(C30,LEN(C30)-1,1),"〇") -> 〇岡 〇希 | E30: 42363 | F30: 大阪府 高槻市 | G30: 8551025151 | H30: 令和7年2月1日から令和8年1月31日まで | J30: =IF(I30<>"",SUBSTITUTE(REPLACE(I30,1,1,"0"),MID(I30,LEN(I30)-1,1),"0"),"") | K30: 利用中
A31: 松田 みずほ | B31: =SUBSTITUTE(REPLACE(A31,1,1,"〇"),MID(A31,LEN(A31)-1,1),"〇") -> 〇田 み〇ほ | C31: 松田 悠希 | D31: =SUBSTITUTE(REPLACE(C31,1,1,"〇"),MID(C31,LEN(C31)-1,1),"〇") -> 〇田 〇希 | E31: 41053 | F31: 大阪府 高槻市 | G31: 8551022505 | H31: 令和6年7月1日から令和7年6月30日まで | J31: =IF(I31<>"",SUBSTITUTE(REPLACE(I31,1,1,"0"),MID(I31,LEN(I31)-1,1),"0"),"") | K31: 利用中
A32: 松村 珠代 | B32: =SUBSTITUTE(REPLACE(A32,1,1,"〇"),MID(A32,LEN(A32)-1,1),"〇") -> 〇村 〇代 | C32: 松村 晴道 | D32: =SUBSTITUTE(REPLACE(C32,1,1,"〇"),MID(C32,LEN(C32)-1,1),"〇") -> 〇村 〇道 | E32: 40470 | F32: 大阪府 高槻市 | G32: 8551056768 | H32: 令和6年12月1日から令和7年11月30日まで | I32: 072-674-5356 | J32: =IF(I32<>"",SUBSTITUTE(REPLACE(I32,1,1,"0"),MID(I32,LEN(I32)-1,1),"0"),"") -> 072-674-0306 | K32: 利用中
A33: 松村 珠代 | B33: =SUBSTITUTE(REPLACE(A33,1,1,"〇"),MID(A33,LEN(A33)-1,1),"〇") -> 〇村 〇代 | C33: 松村 一花 | D33: =SUBSTITUTE(REPLACE(C33,1,1,"〇"),MID(C33,LEN(C33)-1,1),"〇") -> 〇村 〇花 | E33: 41504 | F33: 大阪府 高槻市 | G33: 8551058061 | H33: 令和6年10月1日から令和7年9月30日まで | I33: 072-674-5356 | J33: =IF(I33<>"",SUBSTITUTE(REPLACE(I33,1,1,"0"),MID(I33,LEN(I33)-1,1),"0"),"") -> 072-674-0306 | K33: 利用中
A34: 松本 豊美 | B34: =SUBSTITUTE(REPLACE(A34,1,1,"〇"),MID(A34,LEN(A34)-1,1),"〇") -> 〇本 〇美 | C34: 松本 理佑 | D34: =SUBSTITUTE(REPLACE(C34,1,1,"〇"),MID(C34,LEN(C34)-1,1),"〇") -> 〇本 〇佑 | E34: 41869 | F34: 大阪府 高槻市 | G34: 8551021952 | H34: 令和6年10月1日から令和7年9月30日まで | I34: 726699797 | J34: =IF(I34<>"",SUBSTITUTE(REPLACE(I34,1,1,"0"),MID(I34,LEN(I34)-1,1),"0"),"") -> 026600707 | K34: 利用中
A35: 三浦 麻美 | B35: =SUBSTITUTE(REPLACE(A35,1,1,"〇"),MID(A35,LEN(A35)-1,1),"〇") -> 〇浦 〇美 | C35: 三浦 峻二朗 | D35: =SUBSTITUTE(REPLACE(C35,1,1,"〇"),MID(C35,LEN(C35)-1,1),"〇") -> 〇浦 峻〇朗 | E35: 41938 | F35: 大阪府 高槻市 | G35: 8551025110 | H35: 令和6年12月1日から令和7年11月30日まで | J35: =IF(I35<>"",SUBSTITUTE(REPLACE(I35,1,1,"0"),MID(I35,LEN(I35)-1,1),"0"),"") | K35: 利用中
A36: 満仲 絵里子 | B36: =SUBSTITUTE(REPLACE(A36,1,1,"〇"),MID(A36,LEN(A36)-1,1),"〇") -> 〇仲 絵〇子 | C36: 満仲 雄大 | D36: =SUBSTITUTE(REPLACE(C36,1,1,"〇"),MID(C36,LEN(C36)-1,1),"〇") -> 〇仲 〇大 | E36: 42619 | F36: 大阪府 高槻市 | G36: 8551028023 | H36: 令和6年11月1日から令和7年10月31日まで | J36: =IF(I36<>"",SUBSTITUTE(REPLACE(I36,1,1,"0"),MID(I36,LEN(I36)-1,1),"0"),"") | K36: 利用中
A37: 村山 智美 | B37: =SUBSTITUTE(REPLACE(A37,1,1,"〇"),MID(A37,LEN(A37)-1,1),"〇") -> 〇山 〇美 | C37: 村山 海渡 | D37: =SUBSTITUTE(REPLACE(C37,1,1,"〇"),MID(C37,LEN(C37)-1,1),"〇") -> 〇山 〇渡 | E37: 42548 | F37: 大阪府 高槻市 | G37: 8551034005 | H37: 令和6年8月1日から令和7年7月31日まで | I37: 072-647-5493 | J37: =IF(I37<>"",SUBSTITUTE(REPLACE(I37,1,1,"0"),MID(I37,LEN(I37)-1,1),"0"),"") -> 072-647-5403 | K37: 利用中
A38: 村山 智美 | B38: =SUBSTITUTE(REPLACE(A38,1,1,"〇"),MID(A38,LEN(A38)-1,1),"〇") -> 〇山 〇美 | C38: 村山 聡美 | D38: =SUBSTITUTE(REPLACE(C38,1,1,"〇"),MID(C38,LEN(C38)-1,1),"〇") -> 〇山 〇美 | E38: 43168 | F38: 大阪府 高槻市 | G38: 8551034013 | H38: 令和7年5月1日から令和8年4月30日まで | I38: 072-647-5493 | J38: =IF(I38<>"",SUBSTITUTE(REPLACE(I38,1,1,"0"),MID(I38,LEN(I38)-1,1),"0"),"") -> 072-647-5403 | K38: 利用中
A39: 森本 響子 | B39: =SUBSTITUTE(REPLACE(A39,1,1,"〇"),MID(A39,LEN(A39)-1,1),"〇") -> 〇本 〇子 | C39: 森本 雄詠 | D39: =SUBSTITUTE(REPLACE(C39,1,1,"〇"),MID(C39,LEN(C39)-1,1),"〇") -> 〇本 〇詠 | E39: 41141 | F39: 大阪府 高槻市 | G39: 8551017554 | H39: 令和6年10月1日から令和7年9月30日まで | J39: =IF(I39<>"",SUBSTITUTE(REPLACE(I39,1,1,"0"),MID(I39,LEN(I39)-1,1),"0"),"") | K39: 利用中
A40: 森本 響子 | B40: =SUBSTITUTE(REPLACE(A40,1,1,"〇"),MID(A40,LEN(A40)-1,1),"〇") -> 〇本 〇子 | C40: 森本 凱翔 | D40: =SUBSTITUTE(REPLACE(C40,1,1,"〇"),MID(C40,LEN(C40)-1,1),"〇") -> 〇本 〇翔 | E40: 41837 | F40: 大阪府 高槻市 | G40: 8551028254 | H40: 令和6年9月1日から令和7年8月31日まで | J40: =IF(I40<>"",SUBSTITUTE(REPLACE(I40,1,1,"0"),MID(I40,LEN(I40)-1,1),"0"),"") | K40: 利用中
...

Sheet 職員情報CSV
A1: 所属 | B1: 社員番号 | C1: 職員名 | D1: 職員名（伏字） | E1: 職員カナ | F1: 職員カナ（伏字） | G1: 入社年月日 | H1: 退社年月日 | I1: 郵便番号 | J1: 都道府県 | K1: 市区町村 | L1: 町名以下 | M1: 建物名 | N1: 職員電話番号 | O1: 職員電話番号（伏字） | P1: 職員携帯電話番号 | Q1: 職員携帯電話番号（伏字） | R1: 職員Eメールアドレス | S1: 雇用形態 | T1: 在職状況 | U1: 介護支援専門員 | V1: 介護福祉士 | W1: ホームヘルパー1級 | X1: ホームヘルパー2級 | Y1: 看護師 | Z1: 准看護師 | AA1: 保健師 | AB1: 理学療法士 | AC1: 作業療法士 | AD1: 言語聴覚士 | AE1: 医師 | AF1: 薬剤師 | AG1: 管理栄養士 | AH1: 歯科衛生士 | AI1: 柔道整復師 | AJ1: あん摩マッサージ指圧師 | AK1: 社会福祉主事 | AL1: 社会福祉士 | AM1: 精神保健福祉士 | AN1: 義肢装具士 | AO1: 介護職員基礎研修 | AP1: 介護職員初任者研修 | AQ1: 介護福祉士実務者研修 | AR1: 福祉住環境コーディネーター1級 | AS1: 福祉住環境コーディネーター2級 | AT1: 福祉住環境コーディネーター3級 | AU1: 居宅介護職員初任者研修課程 | AV1: 障害者居宅介護従業者基礎研修課程 | AW1: 重度訪問介護従業者養成研修(基礎) | AX1: 重度訪問介護従業者養成研修(追加) | AY1: 行動援護従業者養成研修 | AZ1: 同行援護従業者養成研修(一般) | BA1: 同行援護従業者養成研修(応用) | BB1: 視覚障害者ガイド養成研修修了者 | BC1: 全身性障害者ガイド養成研修修了者 | BD1: 知的障害者ガイド養成研修修了者 | BE1: 児童発達支援管理責任者 | BF1: 心理士 | BG1: 児童指導員 | BH1: 調理師
A2: 放課後等デイサービス きららステム西冠 | C2: 佐藤 裕美 | D2: =SUBSTITUTE(REPLACE(C2,1,1,"〇"),MID(C2,LEN(C2)-1,1),"〇") -> 〇藤 〇美 | E2: サトウ ヒロミ | F2: =SUBSTITUTE(REPLACE(E2,1,1,"〇"),MID(E2,LEN(E2)-1,1),"〇") -> 〇トウ ヒ〇ミ | O2: =IF(N2<>"",SUBSTITUTE(REPLACE(N2,1,1,"0"),MID(N2,LEN(N2)-1,1),"0"),"") | Q2: =IF(P2<>"",SUBSTITUTE(REPLACE(P2,1,1,"0"),MID(P2,LEN(P2)-1,1),"0"),"") | S2: 常勤 | T2: 在職中
A3: 放課後等デイサービス きららステム西冠 | C3: 高木 亜紗美 | D3: =SUBSTITUTE(REPLACE(C3,1,1,"〇"),MID(C3,LEN(C3)-1,1),"〇") -> 〇木 亜〇美 | E3: タカギ アサミ | F3: =SUBSTITUTE(REPLACE(E3,1,1,"〇"),MID(E3,LEN(E3)-1,1),"〇") -> 〇カギ ア〇ミ | H3: 45565 | O3: =IF(N3<>"",SUBSTITUTE(REPLACE(N3,1,1,"0"),MID(N3,LEN(N3)-1,1),"0"),"") | Q3: =IF(P3<>"",SUBSTITUTE(REPLACE(P3,1,1,"0"),MID(P3,LEN(P3)-1,1),"0"),"") | S3: 常勤 | T3: 退社済
A4: 放課後等デイサービス きららステム西冠 | C4: 脇本 秀史 | D4: =SUBSTITUTE(REPLACE(C4,1,1,"〇"),MID(C4,LEN(C4)-1,1),"〇") -> 〇本 〇史 | E4: ワキモト ヒデシ | F4: =SUBSTITUTE(REPLACE(E4,1,1,"〇"),MID(E4,LEN(E4)-1,1),"〇") -> 〇キモト ヒ〇シ | O4: =IF(N4<>"",SUBSTITUTE(REPLACE(N4,1,1,"0"),MID(N4,LEN(N4)-1,1),"0"),"") | Q4: =IF(P4<>"",SUBSTITUTE(REPLACE(P4,1,1,"0"),MID(P4,LEN(P4)-1,1),"0"),"") | S4: 常勤 | T4: 在職中
A5: 放課後等デイサービス きららステム西冠 | C5: 秋田 まなみ | D5: =SUBSTITUTE(REPLACE(C5,1,1,"〇"),MID(C5,LEN(C5)-1,1),"〇") -> 〇田 ま〇み | E5: アキタ マナミ | F5: =SUBSTITUTE(REPLACE(E5,1,1,"〇"),MID(E5,LEN(E5)-1,1),"〇") -> 〇キタ マ〇ミ | H5: 45553 | O5: =IF(N5<>"",SUBSTITUTE(REPLACE(N5,1,1,"0"),MID(N5,LEN(N5)-1,1),"0"),"") | Q5: =IF(P5<>"",SUBSTITUTE(REPLACE(P5,1,1,"0"),MID(P5,LEN(P5)-1,1),"0"),"") | S5: 常勤 | T5: 退社済
A6: 放課後等デイサービス きららステム西冠 | C6: 堀内 千弘 | D6: =SUBSTITUTE(REPLACE(C6,1,1,"〇"),MID(C6,LEN(C6)-1,1),"〇") -> 〇内 〇弘 | E6: ホリウチ チヒロ | F6: =SUBSTITUTE(REPLACE(E6,1,1,"〇"),MID(E6,LEN(E6)-1,1),"〇") -> 〇リウチ チ〇ロ | H6: 45747 | O6: =IF(N6<>"",SUBSTITUTE(REPLACE(N6,1,1,"0"),MID(N6,LEN(N6)-1,1),"0"),"") | Q6: =IF(P6<>"",SUBSTITUTE(REPLACE(P6,1,1,"0"),MID(P6,LEN(P6)-1,1),"0"),"") | S6: 常勤 | T6: 退社済
A7: 放課後等デイサービス きららステム西冠 | C7: 伊神 智哉 | D7: =SUBSTITUTE(REPLACE(C7,1,1,"〇"),MID(C7,LEN(C7)-1,1),"〇") -> 〇神 〇哉 | E7: イカミ トモヤ | F7: =SUBSTITUTE(REPLACE(E7,1,1,"〇"),MID(E7,LEN(E7)-1,1),"〇") -> 〇カミ ト〇ヤ | O7: =IF(N7<>"",SUBSTITUTE(REPLACE(N7,1,1,"0"),MID(N7,LEN(N7)-1,1),"0"),"") | Q7: =IF(P7<>"",SUBSTITUTE(REPLACE(P7,1,1,"0"),MID(P7,LEN(P7)-1,1),"0"),"") | S7: 常勤 | T7: 在職中
A8: 放課後等デイサービス きららステム西冠 | C8: 中辻 幸二 | D8: =SUBSTITUTE(REPLACE(C8,1,1,"〇"),MID(C8,LEN(C8)-1,1),"〇") -> 〇辻 〇二 | E8: ナカツジ コウジ | F8: =SUBSTITUTE(REPLACE(E8,1,1,"〇"),MID(E8,LEN(E8)-1,1),"〇") -> 〇カツジ コ〇ジ | O8: =IF(N8<>"",SUBSTITUTE(REPLACE(N8,1,1,"0"),MID(N8,LEN(N8)-1,1),"0"),"") | Q8: =IF(P8<>"",SUBSTITUTE(REPLACE(P8,1,1,"0"),MID(P8,LEN(P8)-1,1),"0"),"") | S8: 非常勤 | T8: 在職中 | BG8: 取得日不明
A9: 放課後等デイサービス きららステム西冠 | C9: 佐藤 匠 | D9: =SUBSTITUTE(REPLACE(C9,1,1,"〇"),MID(C9,LEN(C9)-1,1),"〇") -> 〇藤〇匠 | E9: サトウ タクミ | F9: =SUBSTITUTE(REPLACE(E9,1,1,"〇"),MID(E9,LEN(E9)-1,1),"〇") -> 〇トウ タ〇ミ | H9: 45716 | O9: =IF(N9<>"",SUBSTITUTE(REPLACE(N9,1,1,"0"),MID(N9,LEN(N9)-1,1),"0"),"") | Q9: =IF(P9<>"",SUBSTITUTE(REPLACE(P9,1,1,"0"),MID(P9,LEN(P9)-1,1),"0"),"") | S9: 非常勤 | T9: 退社済
A10: 放課後等デイサービス きららステム西冠 | C10: 稲垣 敏和 | D10: =SUBSTITUTE(REPLACE(C10,1,1,"〇"),MID(C10,LEN(C10)-1,1),"〇") -> 〇垣 〇和 | E10: イナガキ トシカズ | F10: =SUBSTITUTE(REPLACE(E10,1,1,"〇"),MID(E10,LEN(E10)-1,1),"〇") -> 〇ナガキ トシ〇ズ | O10: =IF(N10<>"",SUBSTITUTE(REPLACE(N10,1,1,"0"),MID(N10,LEN(N10)-1,1),"0"),"") | Q10: =IF(P10<>"",SUBSTITUTE(REPLACE(P10,1,1,"0"),MID(P10,LEN(P10)-1,1),"0"),"") | S10: 非常勤 | T10: 在職中 | BG10: 取得日不明
A11: 放課後等デイサービス きららステム西冠 | C11: 佐能 美弥子 | D11: =SUBSTITUTE(REPLACE(C11,1,1,"〇"),MID(C11,LEN(C11)-1,1),"〇") -> 〇能 美〇子 | E11: サノウ ミヤコ | F11: =SUBSTITUTE(REPLACE(E11,1,1,"〇"),MID(E11,LEN(E11)-1,1),"〇") -> 〇ノウ ミ〇コ | O11: =IF(N11<>"",SUBSTITUTE(REPLACE(N11,1,1,"0"),MID(N11,LEN(N11)-1,1),"0"),"") | Q11: =IF(P11<>"",SUBSTITUTE(REPLACE(P11,1,1,"0"),MID(P11,LEN(P11)-1,1),"0"),"") | S11: 非常勤 | T11: 在職中 | AC11: 取得日不明
A12: 放課後等デイサービス きららステム西冠 | C12: 竹内 正明 | D12: =SUBSTITUTE(REPLACE(C12,1,1,"〇"),MID(C12,LEN(C12)-1,1),"〇") -> 〇内 〇明 | E12: タケウチ マサアキ | F12: =SUBSTITUTE(REPLACE(E12,1,1,"〇"),MID(E12,LEN(E12)-1,1),"〇") -> 〇ケウチ マサ〇キ | H12: 45747 | I12: 5731184 | O12: =IF(N12<>"",SUBSTITUTE(REPLACE(N12,1,1,"0"),MID(N12,LEN(N12)-1,1),"0"),"") | P12: 8031324065 | Q12: =IF(P12<>"",SUBSTITUTE(REPLACE(P12,1,1,"0"),MID(P12,LEN(P12)-1,1),"0"),"") -> 0031324005 | S12: 常勤 | T12: 退社済 | AW12: 42710 | AY12: 42710 | AZ12: 42710 | BA12: 42710 | BC12: 42710 | BG12: 取得日不明
A13: 放課後等デイサービス きららステム西冠 | C13: 清家 祐子 | D13: =SUBSTITUTE(REPLACE(C13,1,1,"〇"),MID(C13,LEN(C13)-1,1),"〇") -> 〇家 〇子 | E13: セイケ ユウコ | F13: =SUBSTITUTE(REPLACE(E13,1,1,"〇"),MID(E13,LEN(E13)-1,1),"〇") -> 〇イケ ユ〇コ | G13: 45485 | N13: 072-637-3991 | O13: =IF(N13<>"",SUBSTITUTE(REPLACE(N13,1,1,"0"),MID(N13,LEN(N13)-1,1),"0"),"") -> 072-637-3001 | P13: 070-8591-1880 | Q13: =IF(P13<>"",SUBSTITUTE(REPLACE(P13,1,1,"0"),MID(P13,LEN(P13)-1,1),"0"),"") -> 070-0591-1000 | S13: 非常勤 | T13: 在職中
A14: 放課後等デイサービス きららステム西冠 | C14: 西尾 瑠美 | D14: =SUBSTITUTE(REPLACE(C14,1,1,"〇"),MID(C14,LEN(C14)-1,1),"〇") -> 〇尾 〇美 | E14: ニシオ ルミ | F14: =SUBSTITUTE(REPLACE(E14,1,1,"〇"),MID(E14,LEN(E14)-1,1),"〇") -> 〇シオ 〇ミ | O14: =IF(N14<>"",SUBSTITUTE(REPLACE(N14,1,1,"0"),MID(N14,LEN(N14)-1,1),"0"),"") | Q14: =IF(P14<>"",SUBSTITUTE(REPLACE(P14,1,1,"0"),MID(P14,LEN(P14)-1,1),"0"),"") | S14: 常勤 | T14: 在職中 | BG14: 取得日不明
A15: 放課後等デイサービス きららステム西冠 | C15: 東川 直也 | D15: =SUBSTITUTE(REPLACE(C15,1,1,"〇"),MID(C15,LEN(C15)-1,1),"〇") -> 〇川 〇也 | E15: ヒガシカワ ナオヤ | F15: =SUBSTITUTE(REPLACE(E15,1,1,"〇"),MID(E15,LEN(E15)-1,1),"〇") -> 〇ガシカワ ナ〇ヤ | O15: =IF(N15<>"",SUBSTITUTE(REPLACE(N15,1,1,"0"),MID(N15,LEN(N15)-1,1),"0"),"") | Q15: =IF(P15<>"",SUBSTITUTE(REPLACE(P15,1,1,"0"),MID(P15,LEN(P15)-1,1),"0"),"") | S15: 常勤 | T15: 在職中
A16: 放課後等デイサービス きららステム西冠 | C16: 新谷 美春 | D16: =SUBSTITUTE(REPLACE(C16,1,1,"〇"),MID(C16,LEN(C16)-1,1),"〇") -> 〇谷 〇春 | E16: シンタニ ミハル | F16: =SUBSTITUTE(REPLACE(E16,1,1,"〇"),MID(E16,LEN(E16)-1,1),"〇") -> 〇ンタニ ミ〇ル | H16: 45747 | O16: =IF(N16<>"",SUBSTITUTE(REPLACE(N16,1,1,"0"),MID(N16,LEN(N16)-1,1),"0"),"") | Q16: =IF(P16<>"",SUBSTITUTE(REPLACE(P16,1,1,"0"),MID(P16,LEN(P16)-1,1),"0"),"") | S16: 非常勤 | T16: 退社済

Sheet 利用者情報CSV
A1: 利用者名 | B1: 利用者名（伏字） | C1: 利用者カナ | D1: 利用者カナ（伏字） | E1: 利用者生年月日 | F1: 性別 | G1: 郵便番号 | H1: 都道府県 | I1: 市区町村 | J1: 町名以下 | K1: 町名以下（伏字） | L1: 建物名 | M1: 建物名（伏字） | N1: 利用者電話番号 | O1: 利用者電話番号（伏字） | P1: 利用者携帯電話番号 | Q1: 利用者携帯電話番号（伏字） | R1: 請求方法 | S1: 請求送付先 | T1: 請求先氏名 | U1: 続柄 | V1: 請求先郵便番号 | W1: 請求先都道府県 | X1: 請求先市区町村 | Y1: 請求先町名以下 | Z1: 請求先建物名 | AA1: 請求先電話番号 | AB1: 顧客番号 | AC1: 銀行番号 | AD1: 支店番号 | AE1: 口座種別 | AF1: 口座番号 | AG1: 口座名義名カナ | AH1: 利用者状態 | AI1: 備考
A2: 秋山 文子 | B2: =SUBSTITUTE(REPLACE(A2,1,1,"〇"),MID(A2,LEN(A2)-1,1),"〇") -> 〇山 〇子 | C2: アキヤマ フミコ | D2: =SUBSTITUTE(REPLACE(C2,1,1,"〇"),MID(C2,LEN(C2)-1,1),"〇") -> 〇キヤマ フ〇コ | E2: 27990 | F2: 女 | G2: 5690084 | H2: 大阪府 | I2: 高槻市 | J2: 沢良木町18番6-1210号 | K2: =LEFT(SUBSTITUTE(REPLACE(J2,1,1,"〇"),MID(J2,3,1),"〇"),4) -> 〇良〇町 | L2: プラネ高槻ガーデンライフ | M2: =IF(L2<>"",LEFT(SUBSTITUTE(REPLACE(L2,1,1,"〇"),MID(L2,3,1),"〇"),4),"") -> 〇ラ〇高 | O2: =IF(N2<>"",SUBSTITUTE(REPLACE(N2,3,1,"0"),MID(N2,LEN(N2)-1,1),"0"),"") | P2: 080-4134-8874 | Q2: =IF(P2<>"",SUBSTITUTE(REPLACE(P2,2,1,"4"),MID(P2,LEN(P2)-1,1),"0"),"") -> 040-4134-8804 | R2: SMBC口座振替 | S2: 本人 | AE2: なし | AH2: 利用中
A3: 浅井 美貴 | B3: =SUBSTITUTE(REPLACE(A3,1,1,"〇"),MID(A3,LEN(A3)-1,1),"〇") -> 〇井 〇貴 | C3: アサイ ミキ | D3: =SUBSTITUTE(REPLACE(C3,1,1,"〇"),MID(C3,LEN(C3)-1,1),"〇") -> 〇サイ 〇キ | E3: 27912 | F3: 女 | G3: 5690826 | H3: 大阪府 | I3: 高槻市 | J3: 寿町2丁目25番25号 | K3: =LEFT(SUBSTITUTE(REPLACE(J3,1,1,"〇"),MID(J3,3,1),"〇"),4) -> 〇町〇丁 | L3: シャトレーコトブキ101号 | M3: =IF(L3<>"",LEFT(SUBSTITUTE(REPLACE(L3,1,1,"〇"),MID(L3,3,1),"〇"),4),"") -> 〇ャ〇レ | O3: =IF(N3<>"",SUBSTITUTE(REPLACE(N3,3,1,"0"),MID(N3,LEN(N3)-1,1),"0"),"") | P3: 080-2433-8373 | Q3: =IF(P3<>"",SUBSTITUTE(REPLACE(P3,2,1,"4"),MID(P3,LEN(P3)-1,1),"0"),"") -> 040-2433-8303 | R3: 集金 | S3: 本人 | AE3: なし | AH3: 利用中
A4: 熱田 薫 | B4: =SUBSTITUTE(REPLACE(A4,1,1,"〇"),MID(A4,LEN(A4)-1,1),"〇") -> 〇田〇薫 | C4: アツタ カオル | D4: =SUBSTITUTE(REPLACE(C4,1,1,"〇"),MID(C4,LEN(C4)-1,1),"〇") -> 〇ツタ カ〇ル | E4: 31486 | F4: 女 | G4: 5690056 | H4: 大阪府 | I4: 高槻市 | J4: 城南町3丁目12番9号 | K4: =LEFT(SUBSTITUTE(REPLACE(J4,1,1,"〇"),MID(J4,3,1),"〇"),4) -> 〇南〇3 | M4: =IF(L4<>"",LEFT(SUBSTITUTE(REPLACE(L4,1,1,"〇"),MID(L4,3,1),"〇"),4),"") | O4: =IF(N4<>"",SUBSTITUTE(REPLACE(N4,3,1,"0"),MID(N4,LEN(N4)-1,1),"0"),"") | P4: 070-4440-8994 | Q4: =IF(P4<>"",SUBSTITUTE(REPLACE(P4,2,1,"4"),MID(P4,LEN(P4)-1,1),"0"),"") -> 040-4440-8004 | R4: 集金 | S4: 本人 | AE4: なし | AH4: 利用中
A5: 天野 千寿子 | B5: =SUBSTITUTE(REPLACE(A5,1,1,"〇"),MID(A5,LEN(A5)-1,1),"〇") -> 〇野 千〇子 | C5: アマノ チズコ | D5: =SUBSTITUTE(REPLACE(C5,1,1,"〇"),MID(C5,LEN(C5)-1,1),"〇") -> 〇マノ チ〇コ | E5: 30680 | F5: 女 | G5: 5690082 | H5: 大阪府 | I5: 高槻市 | J5: 明野町５番２０－２０７号 | K5: =LEFT(SUBSTITUTE(REPLACE(J5,1,1,"〇"),MID(J5,3,1),"〇"),4) -> 〇野〇５ | M5: =IF(L5<>"",LEFT(SUBSTITUTE(REPLACE(L5,1,1,"〇"),MID(L5,3,1),"〇"),4),"") | O5: =IF(N5<>"",SUBSTITUTE(REPLACE(N5,3,1,"0"),MID(N5,LEN(N5)-1,1),"0"),"") | P5: 080-5311-5008 | Q5: =IF(P5<>"",SUBSTITUTE(REPLACE(P5,2,1,"4"),MID(P5,LEN(P5)-1,1),"0"),"") -> 040-5311-5008 | R5: SMBC口座振替 | S5: 本人 | AE5: なし | AH5: 利用中
A6: 網野 郁絵 | B6: =SUBSTITUTE(REPLACE(A6,1,1,"〇"),MID(A6,LEN(A6)-1,1),"〇") -> 〇野 〇絵 | C6: アミノ イクエ | D6: =SUBSTITUTE(REPLACE(C6,1,1,"〇"),MID(C6,LEN(C6)-1,1),"〇") -> 〇ミノ イ〇エ | E6: 28924 | F6: 女 | G6: 5690823 | H6: 大阪府 | I6: 高槻市 | J6: 芝生町２丁目５８番７号 | K6: =LEFT(SUBSTITUTE(REPLACE(J6,1,1,"〇"),MID(J6,3,1),"〇"),4) -> 〇生〇２ | M6: =IF(L6<>"",LEFT(SUBSTITUTE(REPLACE(L6,1,1,"〇"),MID(L6,3,1),"〇"),4),"") | O6: =IF(N6<>"",SUBSTITUTE(REPLACE(N6,3,1,"0"),MID(N6,LEN(N6)-1,1),"0"),"") | P6: 070-1773-0310 | Q6: =IF(P6<>"",SUBSTITUTE(REPLACE(P6,2,1,"4"),MID(P6,LEN(P6)-1,1),"0"),"") -> 040-0773-0300 | R6: SMBC口座振替 | S6: 本人 | AE6: なし | AH6: 利用中
A7: 家里 夏子 | B7: =SUBSTITUTE(REPLACE(A7,1,1,"〇"),MID(A7,LEN(A7)-1,1),"〇") -> 〇里 〇子 | C7: イエサト ナツコ | D7: =SUBSTITUTE(REPLACE(C7,1,1,"〇"),MID(C7,LEN(C7)-1,1),"〇") -> 〇エサト ナ〇コ | E7: 27272 | F7: 女 | G7: 5690095 | H7: 大阪府 | I7: 高槻市 | J7: 八丁西町８番２１ー２０１号 | K7: =LEFT(SUBSTITUTE(REPLACE(J7,1,1,"〇"),MID(J7,3,1),"〇"),4) -> 〇丁〇町 | M7: =IF(L7<>"",LEFT(SUBSTITUTE(REPLACE(L7,1,1,"〇"),MID(L7,3,1),"〇"),4),"") | O7: =IF(N7<>"",SUBSTITUTE(REPLACE(N7,3,1,"0"),MID(N7,LEN(N7)-1,1),"0"),"") | P7: 090-1761-8380 | Q7: =IF(P7<>"",SUBSTITUTE(REPLACE(P7,2,1,"4"),MID(P7,LEN(P7)-1,1),"0"),"") -> 040-1761-0300 | R7: SMBC口座振替 | S7: 本人 | AE7: なし | AH7: 利用中
A8: 石原 由紀子 | B8: =SUBSTITUTE(REPLACE(A8,1,1,"〇"),MID(A8,LEN(A8)-1,1),"〇") -> 〇原 由〇子 | C8: イシハラ ユキコ | D8: =SUBSTITUTE(REPLACE(C8,1,1,"〇"),MID(C8,LEN(C8)-1,1),"〇") -> 〇シハラ ユ〇コ | E8: 31891 | F8: 女 | G8: 5690043 | H8: 大阪府 | I8: 高槻市 | J8: 竹の内町42番10号 | K8: =LEFT(SUBSTITUTE(REPLACE(J8,1,1,"〇"),MID(J8,3,1),"〇"),4) -> 〇の〇町 | M8: =IF(L8<>"",LEFT(SUBSTITUTE(REPLACE(L8,1,1,"〇"),MID(L8,3,1),"〇"),4),"") | N8: 090-5361-8133 | O8: =IF(N8<>"",SUBSTITUTE(REPLACE(N8,3,1,"0"),MID(N8,LEN(N8)-1,1),"0"),"") -> 090-5061-8100 | Q8: =IF(P8<>"",SUBSTITUTE(REPLACE(P8,2,1,"4"),MID(P8,LEN(P8)-1,1),"0"),"") | R8: SMBC口座振替 | S8: 本人 | AE8: なし | AH8: 利用中
A9: 伊藤 麻紀子 | B9: =SUBSTITUTE(REPLACE(A9,1,1,"〇"),MID(A9,LEN(A9)-1,1),"〇") -> 〇藤 麻〇子 | C9: イトウ マキコ | D9: =SUBSTITUTE(REPLACE(C9,1,1,"〇"),MID(C9,LEN(C9)-1,1),"〇") -> 〇トウ マ〇コ | E9: 26799 | F9: 女 | G9: 5690811 | H9: 大阪府 | I9: 高槻市 | J9: 東五百住町2-24-8 | K9: =LEFT(SUBSTITUTE(REPLACE(J9,1,1,"〇"),MID(J9,3,1),"〇"),4) -> 〇五〇住 | M9: =IF(L9<>"",LEFT(SUBSTITUTE(REPLACE(L9,1,1,"〇"),MID(L9,3,1),"〇"),4),"") | O9: =IF(N9<>"",SUBSTITUTE(REPLACE(N9,3,1,"0"),MID(N9,LEN(N9)-1,1),"0"),"") | P9: 090-3655-1568 | Q9: =IF(P9<>"",SUBSTITUTE(REPLACE(P9,2,1,"4"),MID(P9,LEN(P9)-1,1),"0"),"") -> 040-3055-1508 | R9: SMBC口座振替 | S9: 本人 | AE9: なし | AH9: 利用中
A10: 伊藤 真菜 | B10: =SUBSTITUTE(REPLACE(A10,1,1,"〇"),MID(A10,LEN(A10)-1,1),"〇") -> 〇藤 〇菜 | C10: イトウ マナ | D10: =SUBSTITUTE(REPLACE(C10,1,1,"〇"),MID(C10,LEN(C10)-1,1),"〇") -> 〇トウ 〇ナ | E10: 30909 | F10: 女 | G10: 5690013 | H10: 大阪府 | I10: 高槻市 | J10: 野田3丁目9番1号 | K10: =LEFT(SUBSTITUTE(REPLACE(J10,1,1,"〇"),MID(J10,3,1),"〇"),4) -> 〇田〇丁 | M10: =IF(L10<>"",LEFT(SUBSTITUTE(REPLACE(L10,1,1,"〇"),MID(L10,3,1),"〇"),4),"") | O10: =IF(N10<>"",SUBSTITUTE(REPLACE(N10,3,1,"0"),MID(N10,LEN(N10)-1,1),"0"),"") | P10: 080-1423-6708 | Q10: =IF(P10<>"",SUBSTITUTE(REPLACE(P10,2,1,"4"),MID(P10,LEN(P10)-1,1),"0"),"") -> 040-1423-6708 | R10: SMBC口座振替 | S10: 本人 | AE10: なし | AH10: 利用中
A11: 井上 拓巳 | B11: =SUBSTITUTE(REPLACE(A11,1,1,"〇"),MID(A11,LEN(A11)-1,1),"〇") -> 〇上 〇巳 | C11: イノウエ タクミ | D11: =SUBSTITUTE(REPLACE(C11,1,1,"〇"),MID(C11,LEN(C11)-1,1),"〇") -> 〇ノウエ タ〇ミ | E11: 34459 | F11: 男 | G11: 5690822 | H11: 大阪府 | I11: 高槻市 | J11: 津之江町１丁目２５番３５号の２ | K11: =LEFT(SUBSTITUTE(REPLACE(J11,1,1,"〇"),MID(J11,3,1),"〇"),4) -> 〇之〇町 | M11: =IF(L11<>"",LEFT(SUBSTITUTE(REPLACE(L11,1,1,"〇"),MID(L11,3,1),"〇"),4),"") | O11: =IF(N11<>"",SUBSTITUTE(REPLACE(N11,3,1,"0"),MID(N11,LEN(N11)-1,1),"0"),"") | P11: 080-3030-2181 | Q11: =IF(P11<>"",SUBSTITUTE(REPLACE(P11,2,1,"4"),MID(P11,LEN(P11)-1,1),"0"),"") -> 040-3030-2101 | R11: SMBC口座振替 | S11: 本人 | AE11: なし | AH11: 利用中
A12: 今西 由佳 | B12: =SUBSTITUTE(REPLACE(A12,1,1,"〇"),MID(A12,LEN(A12)-1,1),"〇") -> 〇西 〇佳 | C12: イマニシ ユカ | D12: =SUBSTITUTE(REPLACE(C12,1,1,"〇"),MID(C12,LEN(C12)-1,1),"〇") -> 〇マニシ 〇カ | E12: 29958 | F12: 女 | G12: 5690821 | H12: 大阪府 | I12: 高槻市 | J12: 津之江北町34-8 | K12: =LEFT(SUBSTITUTE(REPLACE(J12,1,1,"〇"),MID(J12,3,1),"〇"),4) -> 〇之〇北 | M12: =IF(L12<>"",LEFT(SUBSTITUTE(REPLACE(L12,1,1,"〇"),MID(L12,3,1),"〇"),4),"") | O12: =IF(N12<>"",SUBSTITUTE(REPLACE(N12,3,1,"0"),MID(N12,LEN(N12)-1,1),"0"),"") | P12: 070-8940-8321 | Q12: =IF(P12<>"",SUBSTITUTE(REPLACE(P12,2,1,"4"),MID(P12,LEN(P12)-1,1),"0"),"") -> 040-8940-8301 | R12: SMBC口座振替 | S12: 本人 | AE12: なし | AH12: 利用中
A13: 上浦 智美 | B13: =SUBSTITUTE(REPLACE(A13,1,1,"〇"),MID(A13,LEN(A13)-1,1),"〇") -> 〇浦 〇美 | C13: ウエウラ トモミ | D13: =SUBSTITUTE(REPLACE(C13,1,1,"〇"),MID(C13,LEN(C13)-1,1),"〇") -> 〇エウラ ト〇ミ | E13: 31539 | F13: 女 | G13: 5690053 | H13: 大阪府 | I13: 高槻市 | J13: 春日町１３番１１号 | K13: =LEFT(SUBSTITUTE(REPLACE(J13,1,1,"〇"),MID(J13,3,1),"〇"),4) -> 〇日〇１ | M13: =IF(L13<>"",LEFT(SUBSTITUTE(REPLACE(L13,1,1,"〇"),MID(L13,3,1),"〇"),4),"") | N13: 070-8335-5198 | O13: =IF(N13<>"",SUBSTITUTE(REPLACE(N13,3,1,"0"),MID(N13,LEN(N13)-1,1),"0"),"") -> 070-8335-5108 | Q13: =IF(P13<>"",SUBSTITUTE(REPLACE(P13,2,1,"4"),MID(P13,LEN(P13)-1,1),"0"),"") | R13: 集金 | S13: 本人 | AE13: なし | AH13: 利用中
A14: 遠藤 里香 | B14: =SUBSTITUTE(REPLACE(A14,1,1,"〇"),MID(A14,LEN(A14)-1,1),"〇") -> 〇藤 〇香 | C14: エンドウ リカ | D14: =SUBSTITUTE(REPLACE(C14,1,1,"〇"),MID(C14,LEN(C14)-1,1),"〇") -> 〇ンドウ 〇カ | E14: 30620 | F14: 女 | G14: 5690065 | H14: 大阪府 | I14: 高槻市 | J14: 城西町4番52-1103号 | K14: =LEFT(SUBSTITUTE(REPLACE(J14,1,1,"〇"),MID(J14,3,1),"〇"),4) -> 〇西〇4 | M14: =IF(L14<>"",LEFT(SUBSTITUTE(REPLACE(L14,1,1,"〇"),MID(L14,3,1),"〇"),4),"") | O14: =IF(N14<>"",SUBSTITUTE(REPLACE(N14,3,1,"0"),MID(N14,LEN(N14)-1,1),"0"),"") | Q14: =IF(P14<>"",SUBSTITUTE(REPLACE(P14,2,1,"4"),MID(P14,LEN(P14)-1,1),"0"),"") | R14: SMBC口座振替 | S14: 本人 | AE14: なし | AH14: 利用中
A15: 大井 貴美枝 | B15: =SUBSTITUTE(REPLACE(A15,1,1,"〇"),MID(A15,LEN(A15)-1,1),"〇") -> 〇井 貴〇枝 | C15: オオイ キミエ | D15: =SUBSTITUTE(REPLACE(C15,1,1,"〇"),MID(C15,LEN(C15)-1,1),"〇") -> 〇オイ キ〇エ | E15: 26680 | F15: 女 | G15: 5690046 | H15: 大阪府 | I15: 高槻市 | J15: 登町10番15号の1 | K15: =LEFT(SUBSTITUTE(REPLACE(J15,1,1,"〇"),MID(J15,3,1),"〇"),4) -> 〇町〇0 | M15: =IF(L15<>"",LEFT(SUBSTITUTE(REPLACE(L15,1,1,"〇"),MID(L15,3,1),"〇"),4),"") | N15: 072-628-6116 | O15: =IF(N15<>"",SUBSTITUTE(REPLACE(N15,3,1,"0"),MID(N15,LEN(N15)-1,1),"0"),"") -> 070-628-6006 | P15: 090-8523-8623 | Q15: =IF(P15<>"",SUBSTITUTE(REPLACE(P15,2,1,"4"),MID(P15,LEN(P15)-1,1),"0"),"") -> 040-8503-8603 | R15: SMBC口座振替 | S15: 本人 | AE15: なし | AH15: 利用中
A16: 大内 由香 | B16: =SUBSTITUTE(REPLACE(A16,1,1,"〇"),MID(A16,LEN(A16)-1,1),"〇") -> 〇内 〇香 | C16: オオウチ ユカ | D16: =SUBSTITUTE(REPLACE(C16,1,1,"〇"),MID(C16,LEN(C16)-1,1),"〇") -> 〇オウチ 〇カ | E16: 26897 | F16: 女 | G16: 5691144 | H16: 大阪府 | I16: 高槻市 | J16: 大畑町１８番２ | K16: =LEFT(SUBSTITUTE(REPLACE(J16,1,1,"〇"),MID(J16,3,1),"〇"),4) -> 〇畑〇１ | L16: パークスクエア高槻ステーション１２０５号 | M16: =IF(L16<>"",LEFT(SUBSTITUTE(REPLACE(L16,1,1,"〇"),MID(L16,3,1),"〇"),4),"") -> 〇ー〇ス | N16: 072-692-9221 | O16: =IF(N16<>"",SUBSTITUTE(REPLACE(N16,3,1,"0"),MID(N16,LEN(N16)-1,1),"0"),"") -> 070-690-9001 | P16: 090-3536-4083 | Q16: =IF(P16<>"",SUBSTITUTE(REPLACE(P16,2,1,"4"),MID(P16,LEN(P16)-1,1),"0"),"") -> 040-3536-4003 | R16: SMBC口座振替 | S16: 本人 | AE16: なし | AH16: 利用中
A17: 大矢 博美 | B17: =SUBSTITUTE(REPLACE(A17,1,1,"〇"),MID(A17,LEN(A17)-1,1),"〇") -> 〇矢 〇美 | C17: オオヤ ヒロミ | D17: =SUBSTITUTE(REPLACE(C17,1,1,"〇"),MID(C17,LEN(C17)-1,1),"〇") -> 〇オヤ ヒ〇ミ | E17: 28523 | F17: 女 | G17: 5690061 | H17: 大阪府 | I17: 高槻市 | J17: 高西町6番3-703号 | K17: =LEFT(SUBSTITUTE(REPLACE(J17,1,1,"〇"),MID(J17,3,1),"〇"),4) -> 〇西〇6 | M17: =IF(L17<>"",LEFT(SUBSTITUTE(REPLACE(L17,1,1,"〇"),MID(L17,3,1),"〇"),4),"") | O17: =IF(N17<>"",SUBSTITUTE(REPLACE(N17,3,1,"0"),MID(N17,LEN(N17)-1,1),"0"),"") | P17: 090-4291-7878 | Q17: =IF(P17<>"",SUBSTITUTE(REPLACE(P17,2,1,"4"),MID(P17,LEN(P17)-1,1),"0"),"") -> 040-4291-0808 | R17: SMBC口座振替 | S17: 本人 | AE17: なし | AH17: 利用中
